<?xml version="1.0" ?>
<!-- =================================================================================== -->
<!-- |    This document was autogenerated by xacro from dual_arm_mobile_hw.urdf.xacro  | -->
<!-- |    EDITING THIS FILE BY HAND IS NOT RECOMMENDED                                 | -->
<!-- =================================================================================== -->
<robot name="r100-0599" xmlns:ignition="http://gazebosim.org/schema">
  <material name="clearpath_dark_grey">
    <color rgba="0.2 0.2 0.2 1.0"/>
  </material>
  <material name="clearpath_medium_grey">
    <color rgba="0.6 0.6 0.6 1.0"/>
  </material>
  <material name="clearpath_light_grey">
    <color rgba="0.8 0.8 0.8 1.0"/>
  </material>
  <material name="clearpath_yellow">
    <color rgba="0.8 0.8 0.0 1.0"/>
  </material>
  <material name="clearpath_black">
    <color rgba="0.15 0.15 0.15 1.0"/>
  </material>
  <material name="clearpath_white">
    <color rgba="1.0 1.0 1.0 1.0"/>
  </material>
  <material name="clearpath_red">
    <color rgba="1.0 0.0 0.0 1.0"/>
  </material>
  <material name="clearpath_aluminum">
    <color rgba="0.5 0.5 0.5 1"/>
  </material>
  <material name="clearpath_plastic">
    <color rgba="0.1 0.1 0.1   1"/>
  </material>
  <!--
    Base UR robot series xacro macro.

    NOTE this is NOT a URDF. It cannot directly be loaded by consumers
    expecting a flattened '.urdf' file. See the top-level '.xacro' for that
    (but note that .xacro must still be processed by the xacro command).

    This file models the base kinematic chain of a UR robot, which then gets
    parameterised by various configuration files to convert it into a UR3(e),
    UR5(e), UR10(e) or UR16e.

    NOTE the default kinematic parameters (i.e., link lengths, frame locations,
    offsets, etc) do not correspond to any particular robot. They are defaults
    only. There WILL be non-zero offsets between the Forward Kinematics results
    in TF (i.e., robot_state_publisher) and the values reported by the Teach
    Pendant.

    For accurate (and robot-specific) transforms, the 'kinematics_parameters_file'
    parameter MUST point to a .yaml file containing the appropriate values for
    the targeted robot.

    If using the UniversalRobots/Universal_Robots_ROS_Driver, follow the steps
    described in the readme of that repository to extract the kinematic
    calibration from the controller and generate the required .yaml file.

    Main author of the migration to yaml configs Ludovic Delval.

    Contributors to previous versions (in no particular order)

     - Denis Stogl
     - Lovro Ivanov
     - Felix Messmer
     - Kelsey Hawkins
     - Wim Meeussen
     - Shaun Edwards
     - Nadia Hammoudeh Garcia
     - Dave Hershberger
     - G. vd. Hoorn
     - Philip Long
     - Dave Coleman
     - Miguel Prada
     - Mathias Luedtke
     - Marcel Schnirring
     - Felix von Drigalski
     - Felix Exner
     - Jimmy Da Silva
     - Ajit Krisshna N L
     - Muhammad Asif Rana
  -->
  <!--
    NOTE the macro defined in this file is NOT part of the public API of this
          package. Users CANNOT rely on this file being available, or stored in
          this location. Nor can they rely on the existence of the macro.
  -->
  <material name="aluminum">
    <color rgba="0.5 0.5 0.5 1"/>
  </material>
  <material name="plastic">
    <color rgba="0.1 0.1 0.1 1"/>
  </material>
  <!-- TODO: need to figure out how tool_device_name works for 2 arms, /tmp/ttyUR2 (this will be defined in the drivers_to_persist file) -->
  <!-- Platform linear & yaw joints -->
  <link name="world"/>
  <link name="virtual_rail_link_1"/>
  <joint name="linear_x_joint" type="prismatic">
    <axis xyz="1 0 0"/>
    <parent link="world"/>
    <child link="virtual_rail_link_1"/>
    <origin rpy="0 0 0" xyz="0 0 0"/>
    <limit acceleration="10.0" effort="1000.0" lower="-100.0" upper="100.0" velocity="0.2"/>
    <dynamics damping="20.0" friction="500.0"/>
  </joint>
  <link name="virtual_rail_link_2"/>
  <joint name="linear_y_joint" type="prismatic">
    <axis xyz="0 1 0"/>
    <parent link="virtual_rail_link_1"/>
    <child link="virtual_rail_link_2"/>
    <origin rpy="0 0 0" xyz="0 0 0"/>
    <limit acceleration="10.0" effort="1000.0" lower="-100.0" upper="100.0" velocity="0.2"/>
    <dynamics damping="20.0" friction="500.0"/>
  </joint>
  <joint name="rotational_yaw_joint" type="continuous">
    <axis xyz="0 0 1"/>
    <parent link="virtual_rail_link_2"/>
    <child link="base_link"/>
    <origin rpy="0 0 0" xyz="0 0 0"/>
    <limit effort="150.0" velocity="0.2"/>
    <dynamics damping="0" friction="0"/>
  </joint>
  <!-- Chassis -->
  <link name="base_link"/>
  <joint name="base_link_joint" type="fixed">
    <origin rpy="0 0 0" xyz="0 0 0"/>
    <parent link="base_link"/>
    <child link="chassis_link"/>
  </joint>
  <link name="chassis_link">
    <visual>
      <origin rpy="0 0 0" xyz="0 0 0"/>
      <geometry>
        <mesh filename="package://clearpath_platform_description/meshes/r100/body.stl"/>
      </geometry>
      <material name="clearpath_black"/>
    </visual>
    <collision>
      <origin xyz="0 0 0"/>
      <geometry>
        <mesh filename="package://clearpath_platform_description/meshes/r100/body-collision.stl"/>
      </geometry>
    </collision>
    <inertial>
      <origin rpy="1.5707963267948966 0 1.5707963267948966" xyz="0.012 0.002 0.067"/>
      <mass value="165.304"/>
      <inertia ixx="4.4744" ixy="0.03098" ixz="0.003647" iyy="7.1624" iyz="0.1228" izz="4.6155"/>
    </inertial>
  </link>
  <!-- Covers -->
  <joint name="right_side_cover_link_joint" type="fixed">
    <origin rpy="0 0 0" xyz="0 0 0"/>
    <parent link="chassis_link"/>
    <child link="right_side_cover_link"/>
  </joint>
  <joint name="left_side_cover_link_joint" type="fixed">
    <origin rpy="0 0 0" xyz="0 0 0"/>
    <parent link="chassis_link"/>
    <child link="left_side_cover_link"/>
  </joint>
  <link name="left_side_cover_link">
    <visual>
      <origin rpy="0 0 3.141592653589793" xyz="0 0 0"/>
      <geometry>
        <mesh filename="package://clearpath_platform_description/meshes/r100/side-cover.stl"/>
      </geometry>
      <material name="clearpath_yellow"/>
    </visual>
  </link>
  <link name="right_side_cover_link">
    <visual>
      <origin rpy="0 0 0" xyz="0 0 0"/>
      <geometry>
        <mesh filename="package://clearpath_platform_description/meshes/r100/side-cover.stl"/>
      </geometry>
      <material name="clearpath_yellow"/>
    </visual>
  </link>
  <joint name="front_cover_link_joint" type="fixed">
    <origin rpy="0 0 0" xyz="0 0 0"/>
    <parent link="chassis_link"/>
    <child link="front_cover_link"/>
  </joint>
  <link name="front_cover_link">
    <visual>
      <origin rpy="0 0 0" xyz="0 0 0"/>
      <geometry>
        <mesh filename="package://clearpath_platform_description/meshes/r100/end-cover.stl"/>
      </geometry>
      <material name="clearpath_black"/>
    </visual>
  </link>
  <joint name="rear_cover_link_joint" type="fixed">
    <origin rpy="0 0 0" xyz="0 0 0"/>
    <parent link="chassis_link"/>
    <child link="rear_cover_link"/>
  </joint>
  <link name="rear_cover_link">
    <visual>
      <origin rpy="0 0 3.141592653589793" xyz="0 0 0"/>
      <geometry>
        <mesh filename="package://clearpath_platform_description/meshes/r100/end-cover.stl"/>
      </geometry>
      <material name="clearpath_black"/>
    </visual>
  </link>
  <!-- Ligths -->
  <joint name="front_lights_link_joint" type="fixed">
    <origin rpy="0 0 0" xyz="0 0 0"/>
    <parent link="chassis_link"/>
    <child link="front_lights_link"/>
  </joint>
  <joint name="rear_lights_link_joint" type="fixed">
    <origin rpy="0 0 0" xyz="0 0 0"/>
    <parent link="chassis_link"/>
    <child link="rear_lights_link"/>
  </joint>
  <link name="front_lights_link">
    <visual>
      <origin rpy="0 0 0" xyz="0 0 0"/>
      <geometry>
        <mesh filename="package://clearpath_platform_description/meshes/r100/lights.stl"/>
      </geometry>
      <material name="clearpath_white"/>
    </visual>
  </link>
  <link name="rear_lights_link">
    <visual>
      <origin rpy="0 0 3.141592653589793" xyz="0 0 0"/>
      <geometry>
        <mesh filename="package://clearpath_platform_description/meshes/r100/lights.stl"/>
      </geometry>
      <material name="clearpath_red"/>
    </visual>
  </link>
  <!-- Axle -->
  <joint name="axle_joint" type="fixed">
    <origin rpy="0 0 0" xyz="0 0 0.05"/>
    <parent link="chassis_link"/>
    <child link="axle_link"/>
  </joint>
  <link name="axle_link">
    <visual>
      <origin rpy="0 1.5707963267948966 0" xyz="0 0 0"/>
      <geometry>
        <mesh filename="package://clearpath_platform_description/meshes/r100/axle.stl"/>
      </geometry>
      <material name="clearpath_black"/>
    </visual>
  </link>
  <!-- Riser -->
  <joint name="riser_link_joint" type="fixed">
    <origin rpy="0 0 0" xyz="0 0 0.22"/>
    <parent link="chassis_link"/>
    <child link="riser_link"/>
  </joint>
  <link name="riser_link">
    <visual>
      <origin rpy="0 0 0.7853981633974483" xyz="0 0 0.0275"/>
      <geometry>
        <box size="0.493 0.493 0.055"/>
      </geometry>
      <material name="clearpath_light_grey"/>
    </visual>
    <collision>
      <origin rpy="0 0 0.7853981633974483" xyz="0 0 0.0275"/>
      <geometry>
        <box size="0.493 0.493 0.055"/>
      </geometry>
    </collision>
  </link>
  <!-- Top Plate -->
  <joint name="top_link_joint" type="fixed">
    <origin rpy="0 0 0" xyz="0 0 -0.22000000000000003"/>
    <parent link="riser_link"/>
    <child link="top_link"/>
  </joint>
  <link name="top_link">
    <visual>
      <origin rpy="0 0 0" xyz="0 0 0"/>
      <geometry>
        <mesh filename="package://clearpath_platform_description/meshes/r100/top.stl"/>
      </geometry>
      <material name="clearpath_black"/>
    </visual>
    <collision>
      <origin rpy="0 0 0" xyz="0 0 0"/>
      <geometry>
        <mesh filename="package://clearpath_platform_description/meshes/r100/top.stl"/>
      </geometry>
    </collision>
  </link>
  <link name="front_rocker_link">
    <visual>
      <origin rpy="1.5707963267948966 0 1.5707963267948966" xyz="0 0 0"/>
      <geometry>
        <mesh filename="package://clearpath_platform_description/meshes/r100/rocker.stl"/>
      </geometry>
      <material name="clearpath_black"/>
    </visual>
    <inertial>
      <origin rpy="1.5707963267948966 0 1.5707963267948966" xyz="0 0 0"/>
      <mass value="10.267"/>
      <inertia ixx="0.0288" ixy="2.20484e-6" ixz="-1.3145e-5" iyy="0.4324" iyz="1.8944e-3" izz="0.4130"/>
    </inertial>
  </link>
  <joint name="front_rocker" type="fixed">
    <parent link="axle_link"/>
    <child link="front_rocker_link"/>
    <origin rpy="0 0 0" xyz="0.319 0 0"/>
    <axis xyz="1 0 0"/>
    <limit effort="0" lower="-0.08726" upper="0.08726" velocity="0"/>
  </joint>
  <link name="front_left_wheel_link">
    <visual>
      <origin rpy="1.5707963267948966 0 0" xyz="0 0 0"/>
      <geometry>
        <mesh filename="package://clearpath_platform_description/meshes/r100/wheel.stl"/>
      </geometry>
      <material name="clearpath_black"/>
    </visual>
    <collision>
      <origin rpy="1.5707963267948966 0 0" xyz="0 0 0"/>
      <geometry>
        <cylinder length="0.079" radius="0.0759"/>
      </geometry>
    </collision>
    <inertial>
      <origin rpy="0 0 0" xyz="0 0 0"/>
      <mass value="2.5"/>
      <inertia ixx="0.0049007145833333335" ixy="0" ixz="0" iyy="0.0072010124999999986" iyz="0" izz="0.0049007145833333335"/>
    </inertial>
  </link>
  <gazebo reference="front_left_wheel_link">
    <collision>
      <surface>
        <friction>
          <ode>
            <mu>1.0</mu>
            <mu2>0.0</mu2>
            <fdir1 ignition:expressed_in="base_link">1 -1 0</fdir1>
          </ode>
        </friction>
      </surface>
    </collision>
  </gazebo>
  <joint name="front_left_wheel_joint" type="continuous">
    <parent link="front_rocker_link"/>
    <child link="front_left_wheel_link"/>
    <origin rpy="0 0 0" xyz="0 0.27549999999999997 0"/>
    <axis xyz="0 1 0"/>
  </joint>
  <link name="front_right_wheel_link">
    <visual>
      <origin rpy="1.5707963267948966 0 0" xyz="0 0 0"/>
      <geometry>
        <mesh filename="package://clearpath_platform_description/meshes/r100/wheel.stl"/>
      </geometry>
      <material name="clearpath_black"/>
    </visual>
    <collision>
      <origin rpy="1.5707963267948966 0 0" xyz="0 0 0"/>
      <geometry>
        <cylinder length="0.079" radius="0.0759"/>
      </geometry>
    </collision>
    <inertial>
      <origin rpy="0 0 0" xyz="0 0 0"/>
      <mass value="2.5"/>
      <inertia ixx="0.0049007145833333335" ixy="0" ixz="0" iyy="0.0072010124999999986" iyz="0" izz="0.0049007145833333335"/>
    </inertial>
  </link>
  <gazebo reference="front_right_wheel_link">
    <collision>
      <surface>
        <friction>
          <ode>
            <mu>1.0</mu>
            <mu2>0.0</mu2>
            <fdir1 ignition:expressed_in="base_link">1 1 0</fdir1>
          </ode>
        </friction>
      </surface>
    </collision>
  </gazebo>
  <joint name="front_right_wheel_joint" type="continuous">
    <parent link="front_rocker_link"/>
    <child link="front_right_wheel_link"/>
    <origin rpy="0 0 0" xyz="0 -0.27549999999999997 0"/>
    <axis xyz="0 1 0"/>
  </joint>
  <link name="rear_rocker_link">
    <visual>
      <origin rpy="1.5707963267948966 0 1.5707963267948966" xyz="0 0 0"/>
      <geometry>
        <mesh filename="package://clearpath_platform_description/meshes/r100/rocker.stl"/>
      </geometry>
      <material name="clearpath_black"/>
    </visual>
    <inertial>
      <origin rpy="1.5707963267948966 0 1.5707963267948966" xyz="0 0 0"/>
      <mass value="10.267"/>
      <inertia ixx="0.0288" ixy="2.20484e-6" ixz="-1.3145e-5" iyy="0.4324" iyz="1.8944e-3" izz="0.4130"/>
    </inertial>
  </link>
  <joint name="rear_rocker" type="fixed">
    <parent link="axle_link"/>
    <child link="rear_rocker_link"/>
    <origin rpy="0 0 0" xyz="-0.319 0 0"/>
    <axis xyz="1 0 0"/>
    <limit effort="0" velocity="0"/>
  </joint>
  <link name="rear_left_wheel_link">
    <visual>
      <origin rpy="1.5707963267948966 0 0" xyz="0 0 0"/>
      <geometry>
        <mesh filename="package://clearpath_platform_description/meshes/r100/wheel.stl"/>
      </geometry>
      <material name="clearpath_black"/>
    </visual>
    <collision>
      <origin rpy="1.5707963267948966 0 0" xyz="0 0 0"/>
      <geometry>
        <cylinder length="0.079" radius="0.0759"/>
      </geometry>
    </collision>
    <inertial>
      <origin rpy="0 0 0" xyz="0 0 0"/>
      <mass value="2.5"/>
      <inertia ixx="0.0049007145833333335" ixy="0" ixz="0" iyy="0.0072010124999999986" iyz="0" izz="0.0049007145833333335"/>
    </inertial>
  </link>
  <gazebo reference="rear_left_wheel_link">
    <collision>
      <surface>
        <friction>
          <ode>
            <mu>1.0</mu>
            <mu2>0.0</mu2>
            <fdir1 ignition:expressed_in="base_link">1 1 0</fdir1>
          </ode>
        </friction>
      </surface>
    </collision>
  </gazebo>
  <joint name="rear_left_wheel_joint" type="continuous">
    <parent link="rear_rocker_link"/>
    <child link="rear_left_wheel_link"/>
    <origin rpy="0 0 0" xyz="0 0.27549999999999997 0"/>
    <axis xyz="0 1 0"/>
  </joint>
  <link name="rear_right_wheel_link">
    <visual>
      <origin rpy="1.5707963267948966 0 0" xyz="0 0 0"/>
      <geometry>
        <mesh filename="package://clearpath_platform_description/meshes/r100/wheel.stl"/>
      </geometry>
      <material name="clearpath_black"/>
    </visual>
    <collision>
      <origin rpy="1.5707963267948966 0 0" xyz="0 0 0"/>
      <geometry>
        <cylinder length="0.079" radius="0.0759"/>
      </geometry>
    </collision>
    <inertial>
      <origin rpy="0 0 0" xyz="0 0 0"/>
      <mass value="2.5"/>
      <inertia ixx="0.0049007145833333335" ixy="0" ixz="0" iyy="0.0072010124999999986" iyz="0" izz="0.0049007145833333335"/>
    </inertial>
  </link>
  <gazebo reference="rear_right_wheel_link">
    <collision>
      <surface>
        <friction>
          <ode>
            <mu>1.0</mu>
            <mu2>0.0</mu2>
            <fdir1 ignition:expressed_in="base_link">1 -1 0</fdir1>
          </ode>
        </friction>
      </surface>
    </collision>
  </gazebo>
  <joint name="rear_right_wheel_joint" type="continuous">
    <parent link="rear_rocker_link"/>
    <child link="rear_right_wheel_link"/>
    <origin rpy="0 0 0" xyz="0 -0.27549999999999997 0"/>
    <axis xyz="0 1 0"/>
  </joint>
  <gazebo>
    <plugin filename="libignition-gazebo-wheel-slip-system.so" name="ignition::gazebo::systems::WheelSlip">
      <wheel link_name="front_left_wheel_link">
        <slip_compliance_lateral>1.0</slip_compliance_lateral>
        <slip_compliance_longitudinal>1.0</slip_compliance_longitudinal>
        <wheel_normal_force>200</wheel_normal_force>
        <wheel_radius>0.0759</wheel_radius>
      </wheel>
      <wheel link_name="front_right_wheel_link">
        <slip_compliance_lateral>1.0</slip_compliance_lateral>
        <slip_compliance_longitudinal>1.0</slip_compliance_longitudinal>
        <wheel_normal_force>200</wheel_normal_force>
        <wheel_radius>0.0759</wheel_radius>
      </wheel>
      <wheel link_name="rear_left_wheel_link">
        <slip_compliance_lateral>1.0</slip_compliance_lateral>
        <slip_compliance_longitudinal>1.0</slip_compliance_longitudinal>
        <wheel_normal_force>200</wheel_normal_force>
        <wheel_radius>0.0759</wheel_radius>
      </wheel>
      <wheel link_name="rear_right_wheel_link">
        <slip_compliance_lateral>1.0</slip_compliance_lateral>
        <slip_compliance_longitudinal>1.0</slip_compliance_longitudinal>
        <wheel_normal_force>200</wheel_normal_force>
        <wheel_radius>0.0759</wheel_radius>
      </wheel>
    </plugin>
  </gazebo>
  <!-- Internal IMU -->
  <link name="imu_0_link">
    <inertial>
      <mass value="0.001"/>
      <origin rpy="0 0 0" xyz="0 0 0"/>
      <inertia ixx="1e-09" ixy="0.0" ixz="0.0" iyy="1e-09" iyz="0.0" izz="1e-09"/>
    </inertial>
  </link>
  <joint name="imu_0_joint" type="fixed">
    <parent link="chassis_link"/>
    <child link="imu_0_link"/>
    <origin rpy="0 0 0" xyz="0.2085 -0.2902 0.1681"/>
  </joint>
  <gazebo reference="imu_0_link">
    <sensor name="imu_0" type="imu">
      <always_on>true</always_on>
      <update_rate>50</update_rate>
      <visualize>true</visualize>
      <ignition_frame_id>imu_0_link</ignition_frame_id>
    </sensor>
  </gazebo>
  <!-- Mounting Hardpoints -->
  <link name="default_mount"/>
  <joint name="default_mount_joint" type="fixed">
    <parent link="riser_link"/>
    <child link="default_mount"/>
    <origin rpy="0 0 0" xyz="0 0 0.06"/>
  </joint>
  <ros2_control name="r100_hardware" type="system">
    <hardware>
      <plugin>clearpath_hardware_interfaces/PumaHardware</plugin>
    </hardware>
    <joint name="front_left_wheel_joint">
      <command_interface name="velocity"/>
      <state_interface name="position"/>
      <state_interface name="velocity"/>
    </joint>
    <joint name="front_right_wheel_joint">
      <command_interface name="velocity"/>
      <state_interface name="position"/>
      <state_interface name="velocity"/>
    </joint>
    <joint name="rear_left_wheel_joint">
      <command_interface name="velocity"/>
      <state_interface name="position"/>
      <state_interface name="velocity"/>
    </joint>
    <joint name="rear_right_wheel_joint">
      <command_interface name="velocity"/>
      <state_interface name="position"/>
      <state_interface name="velocity"/>
    </joint>
  </ros2_control>
  <link name="lidar2d_0_link">
    <visual>
      <origin rpy="0 0 0" xyz="0 0 0"/>
      <geometry>
        <!-- Origin of this mesh is the base of the bracket. -->
        <mesh filename="package://clearpath_sensors_description/meshes/hokuyo_ust.stl"/>
      </geometry>
      <material name="clearpath_dark_grey"/>
    </visual>
  </link>
  <link name="lidar2d_0_laser">
    <inertial>
      <mass value="1.1"/>
      <origin xyz="0 0 0"/>
      <inertia ixx="0.00307156543804" ixy="0.0" ixz="0.0" iyy="0.0031284904152700005" iyz="0.0" izz="0.00196432421427"/>
    </inertial>
  </link>
  <joint name="lidar2d_0_joint" type="fixed">
    <origin rpy="0.0 0.0 0.0" xyz="0.3922 0.0 0.1856"/>
    <parent link="chassis_link"/>
    <child link="lidar2d_0_link"/>
  </joint>
  <joint name="lidar2d_0_laser_joint" type="fixed">
    <!-- This offset is from the base of the bracket to the LIDAR's focal point. -->
    <origin rpy="0 0 0" xyz="0 0 0.0474"/>
    <parent link="lidar2d_0_link"/>
    <child link="lidar2d_0_laser"/>
  </joint>
  <gazebo reference="lidar2d_0_laser">
    <sensor name="lidar2d_0" type="gpu_lidar">
      <update_rate>50</update_rate>
      <visualize>true</visualize>
      <always_on>true</always_on>
      <ignition_frame_id>lidar2d_0_laser</ignition_frame_id>
      <topic>/sensors/lidar2d_0/scan</topic>
      <lidar>
        <scan>
          <horizontal>
            <samples>540</samples>
            <resolution>1</resolution>
            <min_angle>-2.356</min_angle>
            <max_angle>2.356</max_angle>
          </horizontal>
          <vertical>
            <samples>1</samples>
            <resolution>1</resolution>
            <min_angle>0</min_angle>
            <max_angle>0</max_angle>
          </vertical>
        </scan>
        <range>
          <min>0.05</min>
          <max>25.0</max>
          <resolution>0.01</resolution>
        </range>
      </lidar>
    </sensor>
  </gazebo>
  <link name="lidar2d_1_link">
    <visual>
      <origin rpy="0 0 0" xyz="0 0 0"/>
      <geometry>
        <!-- Origin of this mesh is the base of the bracket. -->
        <mesh filename="package://clearpath_sensors_description/meshes/hokuyo_ust.stl"/>
      </geometry>
      <material name="clearpath_dark_grey"/>
    </visual>
  </link>
  <link name="lidar2d_1_laser">
    <inertial>
      <mass value="1.1"/>
      <origin xyz="0 0 0"/>
      <inertia ixx="0.00307156543804" ixy="0.0" ixz="0.0" iyy="0.0031284904152700005" iyz="0.0" izz="0.00196432421427"/>
    </inertial>
  </link>
  <joint name="lidar2d_1_joint" type="fixed">
    <origin rpy="0.0 0.0 3.14159" xyz="-0.3922 0.0 0.1856"/>
    <parent link="chassis_link"/>
    <child link="lidar2d_1_link"/>
  </joint>
  <joint name="lidar2d_1_laser_joint" type="fixed">
    <!-- This offset is from the base of the bracket to the LIDAR's focal point. -->
    <origin rpy="0 0 0" xyz="0 0 0.0474"/>
    <parent link="lidar2d_1_link"/>
    <child link="lidar2d_1_laser"/>
  </joint>
  <gazebo reference="lidar2d_1_laser">
    <sensor name="lidar2d_1" type="gpu_lidar">
      <update_rate>50</update_rate>
      <visualize>true</visualize>
      <always_on>true</always_on>
      <ignition_frame_id>lidar2d_1_laser</ignition_frame_id>
      <topic>/sensors/lidar2d_1/scan</topic>
      <lidar>
        <scan>
          <horizontal>
            <samples>540</samples>
            <resolution>1</resolution>
            <min_angle>-2.356</min_angle>
            <max_angle>2.356</max_angle>
          </horizontal>
          <vertical>
            <samples>1</samples>
            <resolution>1</resolution>
            <min_angle>0</min_angle>
            <max_angle>0</max_angle>
          </vertical>
        </scan>
        <range>
          <min>0.05</min>
          <max>25.0</max>
          <resolution>0.01</resolution>
        </range>
      </lidar>
    </sensor>
  </gazebo>
  <!-- Link -->
  <link name="lift_left_plate_link">
    <visual>
      <origin rpy="0.0 0.0 0.0" xyz="0.0 0.0 0.0"/>
      <geometry>
        <mesh filename="package://ewellix_description/meshes/tlt500/plate.stl"/>
      </geometry>
      <material name="LightGrey">
        <color rgba="0.7 0.7 0.7 1.0"/>
      </material>
    </visual>
    <collision>
      <origin rpy="0.0 0.0 0.0" xyz="0.0 0.0 0.0075"/>
      <geometry>
        <box size="0.2 0.22 0.015"/>
      </geometry>
      <material name="LightGrey">
        <color rgba="0.7 0.7 0.7 1.0"/>
      </material>
    </collision>
    <inertial>
      <mass value="1.0"/>
      <origin rpy="0.0 0.0 0.0" xyz="0.0 0.0 0.0075"/>
      <inertia ixx="0.004052083333333333" ixy="0.0" ixz="0.0" iyy="0.003352083333333334" iyz="0.0" izz="0.007366666666666667"/>
    </inertial>
  </link>
  <joint name="lift_left_plate_joint" type="fixed">
    <child link="lift_left_plate_link"/>
    <parent link="default_mount"/>
    <origin rpy="0.0 0.0 0.0" xyz="0.0 0.2 0.04"/>
  </joint>
  <joint name="lift_left_base_joint" type="fixed">
    <child link="lift_left_base_link"/>
    <parent link="lift_left_plate_link"/>
    <origin rpy="0.0 0.0 0.0" xyz="0.0 0.0 0.015"/>
  </joint>
  <!-- Link -->
  <link name="lift_left_base_link">
    <visual>
      <origin rpy="0.0 0.0 0.0" xyz="0.0 0.0 -0.0151"/>
      <geometry>
        <mesh filename="package://ewellix_description/meshes/tlt500/long/base.stl"/>
      </geometry>
      <material name="LightGrey">
        <color rgba="0.7 0.7 0.7 1.0"/>
      </material>
    </visual>
    <collision>
      <origin rpy="0.0 0.0 0.0" xyz="0.0 0.0 0.24"/>
      <geometry>
        <box size="0.1654 0.1654 0.48"/>
      </geometry>
      <material name="LightGrey">
        <color rgba="0.7 0.7 0.7 1.0"/>
      </material>
    </collision>
    <inertial>
      <mass value="10.0"/>
      <origin rpy="0.0 0.0 0.0" xyz="0.0 0.0 0.24"/>
      <inertia ixx="0.21479763333333332" ixy="0.0" ixz="0.0" iyy="0.21479763333333332" iyz="0.0" izz="0.04559526666666667"/>
    </inertial>
  </link>
  <!-- Link -->
  <link name="lift_left_lower_link">
    <visual>
      <origin rpy="0.0 0.0 0.0" xyz="0.0 0.0 -0.2721"/>
      <geometry>
        <mesh filename="package://ewellix_description/meshes/tlt500/long/lower.stl"/>
      </geometry>
      <material name="LightGrey">
        <color rgba="0.7 0.7 0.7 1.0"/>
      </material>
    </visual>
    <collision>
      <origin rpy="0.0 0.0 0.0" xyz="0.0 0.0 0.2415"/>
      <geometry>
        <box size="0.1484 0.1484 0.483"/>
      </geometry>
      <material name="LightGrey">
        <color rgba="0.7 0.7 0.7 1.0"/>
      </material>
    </collision>
    <inertial>
      <mass value="10.0"/>
      <origin rpy="0.0 0.0 0.0" xyz="0.0 0.0 0.2415"/>
      <inertia ixx="0.21275963333333334" ixy="0.0" ixz="0.0" iyy="0.21275963333333334" iyz="0.0" izz="0.036704266666666666"/>
    </inertial>
  </link>
  <joint name="lift_left_lower_joint" type="prismatic">
    <child link="lift_left_lower_link"/>
    <parent link="lift_left_base_link"/>
    <origin rpy="0.0 0.0 0.0" xyz="0.0 0.0 0.0"/>
    <limit effort="2000.0" lower="0.0" upper="0.4" velocity="0.025"/>
    <axis xyz="0 0 1"/>
    <dynamics damping="0.01" friction="0.01"/>
    <mimic joint="lift_left_upper_joint" multiplier="0.5"/>
  </joint>
  <!-- Link -->
  <link name="lift_left_upper_link">
    <visual>
      <origin rpy="0.0 0.0 0.0" xyz="0.0 0.0 -0.5151"/>
      <geometry>
        <mesh filename="package://ewellix_description/meshes/tlt500/long/upper.stl"/>
      </geometry>
      <material name="LightGrey">
        <color rgba="0.7 0.7 0.7 1.0"/>
      </material>
    </visual>
    <collision>
      <origin rpy="0.0 0.0 0.0" xyz="0.0 0.0 0.24500000000000005"/>
      <geometry>
        <box size="0.129 0.129 0.4900000000000001"/>
      </geometry>
      <material name="LightGrey">
        <color rgba="0.7 0.7 0.7 1.0"/>
      </material>
    </collision>
    <inertial>
      <mass value="10.0"/>
      <origin rpy="0.0 0.0 0.0" xyz="0.0 0.0 0.24500000000000005"/>
      <inertia ixx="0.21395083333333342" ixy="0.0" ixz="0.0" iyy="0.21395083333333342" iyz="0.0" izz="0.027735"/>
    </inertial>
  </link>
  <joint name="lift_left_upper_joint" type="prismatic">
    <child link="lift_left_upper_link"/>
    <parent link="lift_left_base_link"/>
    <origin rpy="0.0 0.0 0.0" xyz="0.0 0.0 0.025"/>
    <axis xyz="0 0 1"/>
    <limit effort="2000.0" lower="0.0" upper="0.45" velocity="0.025"/>
    <dynamics damping="0.01" friction="0.01"/>
  </joint>
  <!-- Mount -->
  <link name="lift_left_mount"/>
  <joint name="lift_left_mount_joint" type="fixed">
    <child link="lift_left_mount"/>
    <parent link="lift_left_upper_link"/>
    <origin rpy="0.0 0.0 0.0" xyz="0.0 0.0 0.4900000000000001"/>
  </joint>
  <ros2_control name="lift_left_hardware" type="system">
    <hardware>
      <plugin>ewellix_driver/EwellixHardwareInterface</plugin>
      <!--<plugin>mock_components/GenericSystem</plugin>-->
      <!--<param name="port">/dev/clearpath/ewellix_left</param>-->
      <param name="port">/dev/ttyUSB1</param>
      <param name="baud">38400</param>
      <param name="timeout">1000</param>
      <param name="conversion">1600</param>
      <param name="rated_effort">2000</param>
      <param name="tolerance">0.005</param>
    </hardware>
    <joint name="lift_left_upper_joint">
      <command_interface name="position"/>
      <state_interface name="position">
        <param name="initial_value">0.25</param>
      </state_interface>
      <state_interface name="velocity"/>
      <state_interface name="effort"/>
    </joint>
  </ros2_control>
  <ros2_control name="left_arm" type="system">
    <hardware>
      <plugin>ur_robot_driver/URPositionHardwareInterface</plugin>
      <!--<plugin>mock_components/GenericSystem</plugin>-->
      <param name="robot_ip">192.168.131.4</param>
      <param name="script_filename">/opt/ros/humble/share/ur_robot_driver/resources/ros_control.urscript</param>
      <param name="output_recipe_filename">/opt/ros/humble/share/ur_robot_driver/resources/rtde_output_recipe.txt</param>
      <param name="input_recipe_filename">/opt/ros/humble/share/ur_robot_driver/resources/rtde_input_recipe.txt</param>
      <param name="headless_mode">True</param>
      <param name="reverse_port">50001</param>
      <param name="script_sender_port">50002</param>
      <param name="reverse_ip">0.0.0.0</param>
      <param name="script_command_port">50004</param>
      <param name="trajectory_port">50003</param>
      <param name="tf_prefix">left_</param>
      <param name="non_blocking_read">True</param>
      <param name="servoj_gain">2000</param>
      <param name="servoj_lookahead_time">0.03</param>
      <param name="use_tool_communication">True</param>
      <param name="kinematics/hash">calib_12788084448423163542</param>
      <param name="tool_voltage">0</param>
      <param name="tool_parity">0</param>
      <param name="tool_baud_rate">115200</param>
      <param name="tool_stop_bits">1</param>
      <param name="tool_rx_idle_chars">1.5</param>
      <param name="tool_tx_idle_chars">3.5</param>
      <param name="tool_device_name">/dev/ttyUSB0</param>
      <param name="tool_tcp_port">54320</param>
      <param name="keep_alive_count">2</param>
    </hardware>
    <joint name="left_shoulder_pan_joint">
      <command_interface name="position"/>
      <command_interface name="velocity"/>
      <state_interface name="position">
        <!-- initial position for the FakeSystem and simulation -->
        <param name="initial_value">0.0</param>
      </state_interface>
      <state_interface name="velocity"/>
      <state_interface name="effort"/>
    </joint>
    <joint name="left_shoulder_lift_joint">
      <command_interface name="position"/>
      <command_interface name="velocity"/>
      <state_interface name="position">
        <!-- initial position for the FakeSystem and simulation -->
        <param name="initial_value">-1.57</param>
      </state_interface>
      <state_interface name="velocity"/>
      <state_interface name="effort"/>
    </joint>
    <joint name="left_elbow_joint">
      <command_interface name="position"/>
      <command_interface name="velocity"/>
      <state_interface name="position">
        <!-- initial position for the FakeSystem and simulation -->
        <param name="initial_value">0.0</param>
      </state_interface>
      <state_interface name="velocity"/>
      <state_interface name="effort"/>
    </joint>
    <joint name="left_wrist_1_joint">
      <command_interface name="position"/>
      <command_interface name="velocity"/>
      <state_interface name="position">
        <!-- initial position for the FakeSystem and simulation -->
        <param name="initial_value">-1.57</param>
      </state_interface>
      <state_interface name="velocity"/>
      <state_interface name="effort"/>
    </joint>
    <joint name="left_wrist_2_joint">
      <command_interface name="position"/>
      <command_interface name="velocity"/>
      <state_interface name="position">
        <!-- initial position for the FakeSystem and simulation -->
        <param name="initial_value">0.0</param>
      </state_interface>
      <state_interface name="velocity"/>
      <state_interface name="effort"/>
    </joint>
    <joint name="left_wrist_3_joint">
      <command_interface name="position"/>
      <command_interface name="velocity"/>
      <state_interface name="position">
        <!-- initial position for the FakeSystem and simulation -->
        <param name="initial_value">0.0</param>
      </state_interface>
      <state_interface name="velocity"/>
      <state_interface name="effort"/>
    </joint>
    <sensor name="left_tcp_fts_sensor">
      <state_interface name="force.x"/>
      <state_interface name="force.y"/>
      <state_interface name="force.z"/>
      <state_interface name="torque.x"/>
      <state_interface name="torque.y"/>
      <state_interface name="torque.z"/>
    </sensor>
    <sensor name="left_tcp_pose">
      <state_interface name="position.x"/>
      <state_interface name="position.y"/>
      <state_interface name="position.z"/>
      <state_interface name="orientation.x"/>
      <state_interface name="orientation.y"/>
      <state_interface name="orientation.z"/>
      <state_interface name="orientation.w"/>
    </sensor>
    <!-- NOTE The following are joints used only for testing with fake hardware and will change in the future -->
    <gpio name="left_speed_scaling">
      <state_interface name="speed_scaling_factor"/>
      <param name="initial_speed_scaling_factor">1</param>
      <command_interface name="target_speed_fraction_cmd"/>
      <command_interface name="target_speed_fraction_async_success"/>
    </gpio>
    <gpio name="left_gpio">
      <command_interface name="standard_digital_output_cmd_0"/>
      <command_interface name="standard_digital_output_cmd_1"/>
      <command_interface name="standard_digital_output_cmd_2"/>
      <command_interface name="standard_digital_output_cmd_3"/>
      <command_interface name="standard_digital_output_cmd_4"/>
      <command_interface name="standard_digital_output_cmd_5"/>
      <command_interface name="standard_digital_output_cmd_6"/>
      <command_interface name="standard_digital_output_cmd_7"/>
      <command_interface name="standard_digital_output_cmd_8"/>
      <command_interface name="standard_digital_output_cmd_9"/>
      <command_interface name="standard_digital_output_cmd_10"/>
      <command_interface name="standard_digital_output_cmd_11"/>
      <command_interface name="standard_digital_output_cmd_12"/>
      <command_interface name="standard_digital_output_cmd_13"/>
      <command_interface name="standard_digital_output_cmd_14"/>
      <command_interface name="standard_digital_output_cmd_15"/>
      <command_interface name="standard_digital_output_cmd_16"/>
      <command_interface name="standard_digital_output_cmd_17"/>
      <command_interface name="standard_analog_output_cmd_0"/>
      <command_interface name="standard_analog_output_cmd_1"/>
      <command_interface name="analog_output_domain_cmd"/>
      <command_interface name="tool_voltage_cmd"/>
      <command_interface name="io_async_success"/>
      <state_interface name="digital_output_0"/>
      <state_interface name="digital_output_1"/>
      <state_interface name="digital_output_2"/>
      <state_interface name="digital_output_3"/>
      <state_interface name="digital_output_4"/>
      <state_interface name="digital_output_5"/>
      <state_interface name="digital_output_6"/>
      <state_interface name="digital_output_7"/>
      <state_interface name="digital_output_8"/>
      <state_interface name="digital_output_9"/>
      <state_interface name="digital_output_10"/>
      <state_interface name="digital_output_11"/>
      <state_interface name="digital_output_12"/>
      <state_interface name="digital_output_13"/>
      <state_interface name="digital_output_14"/>
      <state_interface name="digital_output_15"/>
      <state_interface name="digital_output_16"/>
      <state_interface name="digital_output_17"/>
      <state_interface name="digital_input_0"/>
      <state_interface name="digital_input_1"/>
      <state_interface name="digital_input_2"/>
      <state_interface name="digital_input_3"/>
      <state_interface name="digital_input_4"/>
      <state_interface name="digital_input_5"/>
      <state_interface name="digital_input_6"/>
      <state_interface name="digital_input_7"/>
      <state_interface name="digital_input_8"/>
      <state_interface name="digital_input_9"/>
      <state_interface name="digital_input_10"/>
      <state_interface name="digital_input_11"/>
      <state_interface name="digital_input_12"/>
      <state_interface name="digital_input_13"/>
      <state_interface name="digital_input_14"/>
      <state_interface name="digital_input_15"/>
      <state_interface name="digital_input_16"/>
      <state_interface name="digital_input_17"/>
      <state_interface name="standard_analog_output_0"/>
      <state_interface name="standard_analog_output_1"/>
      <state_interface name="standard_analog_input_0"/>
      <state_interface name="standard_analog_input_1"/>
      <state_interface name="analog_io_type_0"/>
      <state_interface name="analog_io_type_1"/>
      <state_interface name="analog_io_type_2"/>
      <state_interface name="analog_io_type_3"/>
      <state_interface name="tool_mode"/>
      <state_interface name="tool_output_voltage"/>
      <state_interface name="tool_output_current"/>
      <state_interface name="tool_temperature"/>
      <state_interface name="tool_analog_input_0"/>
      <state_interface name="tool_analog_input_1"/>
      <state_interface name="tool_analog_input_type_0"/>
      <state_interface name="tool_analog_input_type_1"/>
      <state_interface name="robot_mode"/>
      <state_interface name="robot_status_bit_0"/>
      <state_interface name="robot_status_bit_1"/>
      <state_interface name="robot_status_bit_2"/>
      <state_interface name="robot_status_bit_3"/>
      <state_interface name="safety_mode"/>
      <state_interface name="safety_status_bit_0"/>
      <state_interface name="safety_status_bit_1"/>
      <state_interface name="safety_status_bit_2"/>
      <state_interface name="safety_status_bit_3"/>
      <state_interface name="safety_status_bit_4"/>
      <state_interface name="safety_status_bit_5"/>
      <state_interface name="safety_status_bit_6"/>
      <state_interface name="safety_status_bit_7"/>
      <state_interface name="safety_status_bit_8"/>
      <state_interface name="safety_status_bit_9"/>
      <state_interface name="safety_status_bit_10"/>
      <state_interface name="program_running"/>
    </gpio>
    <gpio name="left_payload">
      <command_interface name="mass"/>
      <command_interface name="cog.x"/>
      <command_interface name="cog.y"/>
      <command_interface name="cog.z"/>
      <command_interface name="payload_async_success"/>
    </gpio>
    <gpio name="left_resend_robot_program">
      <command_interface name="resend_robot_program_cmd"/>
      <command_interface name="resend_robot_program_async_success"/>
    </gpio>
    <gpio name="left_hand_back_control">
      <command_interface name="hand_back_control_cmd"/>
      <command_interface name="hand_back_control_async_success"/>
    </gpio>
    <gpio name="left_zero_ftsensor">
      <command_interface name="zero_ftsensor_cmd"/>
      <command_interface name="zero_ftsensor_async_success"/>
    </gpio>
    <gpio name="left_system_interface">
      <state_interface name="initialized"/>
    </gpio>
    <gpio name="left_get_robot_software_version">
      <state_interface name="get_version_major"/>
      <state_interface name="get_version_minor"/>
      <state_interface name="get_version_build"/>
      <state_interface name="get_version_bugfix"/>
    </gpio>
  </ros2_control>
  <!-- Add URDF transmission elements (for ros_control) -->
  <!--<xacro:ur_arm_transmission prefix="${prefix}" hw_interface="${transmission_hw_interface}" />-->
  <!-- Placeholder for ros2_control transmission which don't yet exist -->
  <!-- links -  main serial chain -->
  <link name="left_base_link"/>
  <link name="left_base_link_inertia">
    <visual>
      <origin rpy="0 0 3.141592653589793" xyz="0 0 0"/>
      <geometry>
        <mesh filename="package://ur_description/meshes/ur5e/visual/base.dae"/>
      </geometry>
    </visual>
    <collision>
      <origin rpy="0 0 3.141592653589793" xyz="0 0 0"/>
      <geometry>
        <mesh filename="package://ur_description/meshes/ur5e/collision/base.stl"/>
      </geometry>
    </collision>
    <inertial>
      <mass value="4.0"/>
      <origin rpy="0 0 0" xyz="0 0 0"/>
      <inertia ixx="0.00443333156" ixy="0.0" ixz="0.0" iyy="0.00443333156" iyz="0.0" izz="0.0072"/>
    </inertial>
  </link>
  <link name="left_shoulder_link">
    <visual>
      <origin rpy="0 0 3.141592653589793" xyz="0 0 0"/>
      <geometry>
        <mesh filename="package://ur_description/meshes/ur5e/visual/shoulder.dae"/>
      </geometry>
    </visual>
    <collision>
      <origin rpy="0 0 3.141592653589793" xyz="0 0 0"/>
      <geometry>
        <mesh filename="package://ur_description/meshes/ur5e/collision/shoulder.stl"/>
      </geometry>
    </collision>
    <inertial>
      <mass value="3.761"/>
      <origin rpy="0 0 0" xyz="0.0 -0.00193 -0.02561"/>
      <inertia ixx="0.010267499999999999" ixy="0" ixz="0" iyy="0.010267499999999999" iyz="0" izz="0.00666"/>
    </inertial>
  </link>
  <link name="left_upper_arm_link">
    <visual>
      <origin rpy="1.5707963267948966 0 -1.5707963267948966" xyz="0 0 0.138"/>
      <geometry>
        <mesh filename="package://ur_description/meshes/ur5e/visual/upperarm.dae"/>
      </geometry>
    </visual>
    <collision>
      <origin rpy="1.5707963267948966 0 -1.5707963267948966" xyz="0 0 0.138"/>
      <geometry>
        <mesh filename="package://ur_description/meshes/ur5e/collision/upperarm.stl"/>
      </geometry>
    </collision>
    <inertial>
      <mass value="8.058"/>
      <origin rpy="0 1.570796326794897 0" xyz="-0.2125 0.0 0.11336"/>
      <inertia ixx="0.13388583541666665" ixy="0" ixz="0" iyy="0.13388583541666665" iyz="0" izz="0.0151074"/>
    </inertial>
  </link>
  <link name="left_forearm_link">
    <visual>
      <origin rpy="1.5707963267948966 0 -1.5707963267948966" xyz="0 0 0.007"/>
      <geometry>
        <mesh filename="package://ur_description/meshes/ur5e/visual/forearm.dae"/>
      </geometry>
    </visual>
    <collision>
      <origin rpy="1.5707963267948966 0 -1.5707963267948966" xyz="0 0 0.007"/>
      <geometry>
        <mesh filename="package://ur_description/meshes/ur5e/collision/forearm.stl"/>
      </geometry>
    </collision>
    <inertial>
      <mass value="2.846"/>
      <origin rpy="0 1.570796326794897 0" xyz="-0.2422 0.0 0.0265"/>
      <inertia ixx="0.03120936758333333" ixy="0" ixz="0" iyy="0.03120936758333333" iyz="0" izz="0.004095"/>
    </inertial>
  </link>
  <link name="left_wrist_1_link">
    <visual>
      <origin rpy="1.5707963267948966 0 0" xyz="0 0 -0.127"/>
      <geometry>
        <mesh filename="package://ur_description/meshes/ur5e/visual/wrist1.dae"/>
      </geometry>
    </visual>
    <collision>
      <origin rpy="1.5707963267948966 0 0" xyz="0 0 -0.127"/>
      <geometry>
        <mesh filename="package://ur_description/meshes/ur5e/collision/wrist1.stl"/>
      </geometry>
    </collision>
    <inertial>
      <mass value="1.37"/>
      <origin rpy="0 0 0" xyz="0.0 -0.01634 -0.0018"/>
      <inertia ixx="0.0025599" ixy="0" ixz="0" iyy="0.0025599" iyz="0" izz="0.0021942"/>
    </inertial>
  </link>
  <link name="left_wrist_2_link">
    <visual>
      <origin rpy="0 0 0" xyz="0 0 -0.0997"/>
      <geometry>
        <mesh filename="package://ur_description/meshes/ur5e/visual/wrist2.dae"/>
      </geometry>
    </visual>
    <collision>
      <origin rpy="0 0 0" xyz="0 0 -0.0997"/>
      <geometry>
        <mesh filename="package://ur_description/meshes/ur5e/collision/wrist2.stl"/>
      </geometry>
    </collision>
    <inertial>
      <mass value="1.3"/>
      <origin rpy="0 0 0" xyz="0.0 0.01634 -0.0018"/>
      <inertia ixx="0.0025599" ixy="0" ixz="0" iyy="0.0025599" iyz="0" izz="0.0021942"/>
    </inertial>
  </link>
  <link name="left_wrist_3_link">
    <visual>
      <origin rpy="1.5707963267948966 0 0" xyz="0 0 -0.0989"/>
      <geometry>
        <mesh filename="package://ur_description/meshes/ur5e/visual/wrist3.dae"/>
      </geometry>
    </visual>
    <collision>
      <origin rpy="1.5707963267948966 0 0" xyz="0 0 -0.0989"/>
      <geometry>
        <mesh filename="package://ur_description/meshes/ur5e/collision/wrist3.stl"/>
      </geometry>
    </collision>
    <inertial>
      <mass value="0.365"/>
      <origin rpy="0 0 0" xyz="0.0 0.0 -0.001159"/>
      <inertia ixx="9.890414008333333e-05" ixy="0" ixz="0" iyy="9.890414008333333e-05" iyz="0" izz="0.0001321171875"/>
    </inertial>
  </link>
  <!-- base_joint fixes base_link to the environment -->
  <joint name="left_base_joint" type="fixed">
    <origin rpy="0 0 -0.7853981633974483" xyz="0 0 0"/>
    <parent link="left_arm_mount_plate_2"/>
    <child link="left_base_link"/>
  </joint>
  <!-- joints - main serial chain -->
  <joint name="left_base_link-base_link_inertia" type="fixed">
    <parent link="left_base_link"/>
    <child link="left_base_link_inertia"/>
    <!-- 'base_link' is REP-103 aligned (so X+ forward), while the internal
           frames of the robot/controller have X+ pointing backwards.
           Use the joint between 'base_link' and 'base_link_inertia' (a dummy
           link/frame) to introduce the necessary rotation over Z (of pi rad).
      -->
    <origin rpy="0 0 3.141592653589793" xyz="0 0 0"/>
  </joint>
  <joint name="left_shoulder_pan_joint" type="revolute">
    <parent link="left_base_link_inertia"/>
    <child link="left_shoulder_link"/>
    <origin rpy="0 0 0" xyz="0 0 0.1625"/>
    <axis xyz="0 0 1"/>
    <limit effort="150.0" lower="-6.283185307179586" upper="6.283185307179586" velocity="3.141592653589793"/>
    <dynamics damping="0" friction="0"/>
  </joint>
  <joint name="left_shoulder_lift_joint" type="revolute">
    <parent link="left_shoulder_link"/>
    <child link="left_upper_arm_link"/>
    <origin rpy="1.570796327 0 0" xyz="0 0 0"/>
    <axis xyz="0 0 1"/>
    <limit effort="150.0" lower="-6.283185307179586" upper="6.283185307179586" velocity="3.141592653589793"/>
    <dynamics damping="0" friction="0"/>
  </joint>
  <joint name="left_elbow_joint" type="revolute">
    <parent link="left_upper_arm_link"/>
    <child link="left_forearm_link"/>
    <origin rpy="0 0 0" xyz="-0.425 0 0"/>
    <axis xyz="0 0 1"/>
    <limit effort="150.0" lower="-3.141592653589793" upper="3.141592653589793" velocity="3.141592653589793"/>
    <dynamics damping="0" friction="0"/>
  </joint>
  <joint name="left_wrist_1_joint" type="revolute">
    <parent link="left_forearm_link"/>
    <child link="left_wrist_1_link"/>
    <origin rpy="0 0 0" xyz="-0.3922 0 0.1333"/>
    <axis xyz="0 0 1"/>
    <limit effort="28.0" lower="-6.283185307179586" upper="6.283185307179586" velocity="3.141592653589793"/>
    <dynamics damping="0" friction="0"/>
  </joint>
  <joint name="left_wrist_2_joint" type="revolute">
    <parent link="left_wrist_1_link"/>
    <child link="left_wrist_2_link"/>
    <origin rpy="1.570796327 0 0" xyz="0 -0.0997 -2.044881182297852e-11"/>
    <axis xyz="0 0 1"/>
    <limit effort="28.0" lower="-6.283185307179586" upper="6.283185307179586" velocity="3.141592653589793"/>
    <dynamics damping="0" friction="0"/>
  </joint>
  <joint name="left_wrist_3_joint" type="revolute">
    <parent link="left_wrist_2_link"/>
    <child link="left_wrist_3_link"/>
    <origin rpy="1.570796326589793 3.141592653589793 3.141592653589793" xyz="0 0.0996 -2.042830148012698e-11"/>
    <axis xyz="0 0 1"/>
    <limit effort="28.0" lower="-6.283185307179586" upper="6.283185307179586" velocity="3.141592653589793"/>
    <dynamics damping="0" friction="0"/>
  </joint>
  <link name="left_ft_frame"/>
  <joint name="left_wrist_3_link-ft_frame" type="fixed">
    <parent link="left_wrist_3_link"/>
    <child link="left_ft_frame"/>
    <origin rpy="0 0 0" xyz="0 0 0"/>
  </joint>
  <!-- ROS-Industrial 'base' frame - base_link to UR 'Base' Coordinates transform -->
  <link name="left_base"/>
  <joint name="left_base_link-base_fixed_joint" type="fixed">
    <!-- Note the rotation over Z of pi radians - as base_link is REP-103
           aligned (i.e., has X+ forward, Y+ left and Z+ up), this is needed
           to correctly align 'base' with the 'Base' coordinate system of
           the UR controller.
      -->
    <origin rpy="0 0 3.141592653589793" xyz="0 0 0"/>
    <parent link="left_base_link"/>
    <child link="left_base"/>
  </joint>
  <!-- ROS-Industrial 'flange' frame - attachment point for EEF models -->
  <link name="left_flange"/>
  <joint name="left_wrist_3-flange" type="fixed">
    <parent link="left_wrist_3_link"/>
    <child link="left_flange"/>
    <origin rpy="0 -1.5707963267948966 -1.5707963267948966" xyz="0 0 0"/>
  </joint>
  <!-- ROS-Industrial 'tool0' frame - all-zeros tool frame -->
  <link name="left_tool0"/>
  <joint name="left_flange-tool0" type="fixed">
    <!-- default toolframe - X+ left, Y+ up, Z+ front -->
    <origin rpy="1.5707963267948966 0 1.5707963267948966" xyz="0 0 0"/>
    <parent link="left_flange"/>
    <child link="left_tool0"/>
  </joint>
  <joint name="left_realsense_camera_adapter_joint" type="fixed">
    <!-- The parent link must be read from the robot model it is attached to. -->
    <parent link="left_tool0"/>
    <child link="left_realsense_camera_adapter_link"/>
    <origin rpy="0 0 0" xyz="0 0 0"/>
  </joint>
  <link name="left_realsense_camera_adapter_link">
    <visual>
      <origin rpy="0 0 0" xyz="0 0 0"/>
      <geometry>
        <mesh filename="package://picknik_accessories/descriptions/brackets/ur_realsense_camera_adapter/picknik_ur5_realsense_camera_adapter_rev2.dae"/>
      </geometry>
    </visual>
    <collision>
      <origin rpy="0 0 0" xyz="0 0 0"/>
      <geometry>
        <mesh filename="package://picknik_accessories/descriptions/brackets/ur_realsense_camera_adapter/picknik_ur5_realsense_camera_adapter_rev2_collision.stl"/>
      </geometry>
    </collision>
  </link>
  <link name="left_realsense_camera_adapter_tool0"/>
  <joint name="left_realsense_camera_adapter_tool0_joint" type="fixed">
    <parent link="left_realsense_camera_adapter_link"/>
    <child link="left_realsense_camera_adapter_tool0"/>
    <origin rpy="0 0 0" xyz="0 0 0.007"/>
  </joint>
  <link name="left_d415_mount_link"/>
  <joint name="left_d415_mount_joint" type="fixed">
    <parent link="left_realsense_camera_adapter_link"/>
    <child link="left_d415_mount_link"/>
    <origin rpy="0 -1.4660765716752369 1.5707963267948966" xyz="0 -0.067 0.0171"/>
  </joint>
  <link name="left_l515_mount_link"/>
  <joint name="left_l515_mount_joint" type="fixed">
    <parent link="left_realsense_camera_adapter_link"/>
    <child link="left_l515_mount_link"/>
    <origin rpy="0 -1.4660765716752369 1.5707963267948966" xyz="0 -0.0406 0.0173"/>
  </joint>
  <!-- camera body, with origin at bottom screw mount -->
  <joint name="left_wrist_mounted_camera_joint" type="fixed">
    <origin rpy="0 0 0" xyz="0 0 0"/>
    <parent link="left_d415_mount_link"/>
    <child link="left_wrist_mounted_camera_bottom_screw_frame"/>
  </joint>
  <link name="left_wrist_mounted_camera_bottom_screw_frame"/>
  <joint name="left_wrist_mounted_camera_link_joint" type="fixed">
    <origin rpy="0 0 0" xyz="0 0.02 0.0115"/>
    <parent link="left_wrist_mounted_camera_bottom_screw_frame"/>
    <child link="left_wrist_mounted_camera_link"/>
  </joint>
  <link name="left_wrist_mounted_camera_link">
    <visual>
      <origin rpy="1.5707963267948966 0 1.5707963267948966" xyz="0.00987 -0.02 0"/>
      <geometry>
        <mesh filename="package://realsense2_description/meshes/d415.stl"/>
      </geometry>
      <material name="rs_aluminum">
        <color rgba="0.5 0.5 0.5 1.0"/>
      </material>
    </visual>
    <collision>
      <origin rpy="0 0 0" xyz="0 -0.02 0"/>
      <geometry>
        <box size="0.02005 0.099 0.023"/>
      </geometry>
    </collision>
    <inertial>
      <mass value="0.072"/>
      <!-- The following are not reliable values, and should not be used for modeling -->
      <origin xyz="0 0 0"/>
      <inertia ixx="0.003881243" ixy="0.0" ixz="0.0" iyy="0.000498940" iyz="0.0" izz="0.003879257"/>
    </inertial>
  </link>
  <!-- camera depth joints and links -->
  <joint name="left_wrist_mounted_camera_depth_joint" type="fixed">
    <origin rpy="0 0 0" xyz="0 0 0"/>
    <parent link="left_wrist_mounted_camera_link"/>
    <child link="left_wrist_mounted_camera_depth_frame"/>
  </joint>
  <link name="left_wrist_mounted_camera_depth_frame"/>
  <joint name="left_wrist_mounted_camera_depth_optical_joint" type="fixed">
    <origin rpy="-1.5707963267948966 0 -1.5707963267948966" xyz="0 0 0"/>
    <parent link="left_wrist_mounted_camera_depth_frame"/>
    <child link="left_wrist_mounted_camera_depth_optical_frame"/>
  </joint>
  <link name="left_wrist_mounted_camera_depth_optical_frame"/>
  <!-- camera left IR joints and links -->
  <joint name="left_wrist_mounted_camera_infra1_joint" type="fixed">
    <origin rpy="0 0 0" xyz="0 0.0 0"/>
    <parent link="left_wrist_mounted_camera_link"/>
    <child link="left_wrist_mounted_camera_infra1_frame"/>
  </joint>
  <link name="left_wrist_mounted_camera_infra1_frame"/>
  <joint name="left_wrist_mounted_camera_infra1_optical_joint" type="fixed">
    <origin rpy="-1.5707963267948966 0 -1.5707963267948966" xyz="0 0 0"/>
    <parent link="left_wrist_mounted_camera_infra1_frame"/>
    <child link="left_wrist_mounted_camera_infra1_optical_frame"/>
  </joint>
  <link name="left_wrist_mounted_camera_infra1_optical_frame"/>
  <!-- camera right IR joints and links -->
  <joint name="left_wrist_mounted_camera_infra2_joint" type="fixed">
    <origin rpy="0 0 0" xyz="0 -0.055 0"/>
    <parent link="left_wrist_mounted_camera_link"/>
    <child link="left_wrist_mounted_camera_infra2_frame"/>
  </joint>
  <link name="left_wrist_mounted_camera_infra2_frame"/>
  <joint name="left_wrist_mounted_camera_infra2_optical_joint" type="fixed">
    <origin rpy="-1.5707963267948966 0 -1.5707963267948966" xyz="0 0 0"/>
    <parent link="left_wrist_mounted_camera_infra2_frame"/>
    <child link="left_wrist_mounted_camera_infra2_optical_frame"/>
  </joint>
  <link name="left_wrist_mounted_camera_infra2_optical_frame"/>
  <!-- camera color joints and links -->
  <joint name="left_wrist_mounted_camera_color_joint" type="fixed">
    <origin rpy="0 0 0" xyz="0 0.015 0"/>
    <parent link="left_wrist_mounted_camera_link"/>
    <child link="left_wrist_mounted_camera_color_frame"/>
  </joint>
  <link name="left_wrist_mounted_camera_color_frame"/>
  <joint name="left_wrist_mounted_camera_color_optical_joint" type="fixed">
    <origin rpy="-1.5707963267948966 0 -1.5707963267948966" xyz="0 0 0"/>
    <parent link="left_wrist_mounted_camera_color_frame"/>
    <child link="left_wrist_mounted_camera_color_optical_frame"/>
  </joint>
  <link name="left_wrist_mounted_camera_color_optical_frame"/>
  <gazebo reference="left_wrist_mounted_camera_color_frame">
    <sensor name="left_wrist_mounted_camera_rgbd_sensor" type="rgbd_camera">
      <camera>
        <horizontal_fov>1.047</horizontal_fov>
        <image>
          <width>640</width>
          <height>480</height>
          <format>RGB_INT8</format>
        </image>
        <clip>
          <near>0.1</near>
          <far>5</far>
        </clip>
        <distortion>
          <k1>0.0</k1>
          <k2>0.0</k2>
          <k3>0.0</k3>
          <p1>0.0</p1>
          <p2>0.0</p2>
          <center>0.5 0.5</center>
        </distortion>
        <lens>
          <intrinsics>
            <fx>554.25469</fx>
            <fy>554.25469</fy>
            <cx>320.5</cx>
            <cy>240.5</cy>
            <s>0</s>
          </intrinsics>
          <!-- These need to match the intrinsics above or
            Ignition will default to different default values -->
          <projection>
            <p_fx>554.25469</p_fx>
            <p_fy>554.25469</p_fy>
            <p_cx>320.5</p_cx>
            <p_cy>240.5</p_cy>
            <tx>0</tx>
            <ty>0</ty>
          </projection>
        </lens>
        <noise>
          <type>gaussian</type>
          <mean>0</mean>
          <stddev>0.00</stddev>
        </noise>
        <depth_camera>
          <clip>
            <near>0.25</near>
            <far>5</far>
          </clip>
        </depth_camera>
        <optical_frame_id>left_wrist_mounted_camera_color_optical_frame</optical_frame_id>
      </camera>
      <ignition_frame_id>left_wrist_mounted_camera_color_frame</ignition_frame_id>
      <always_on>1</always_on>
      <update_rate>6</update_rate>
      <visualize>false</visualize>
      <topic>left_wrist_mounted_camera</topic>
      <enable_metrics>false</enable_metrics>
    </sensor>
  </gazebo>
  <joint name="left_ur_to_robotiq_joint" type="fixed">
    <!-- The parent link must be read from the robot model it is attached to. -->
    <parent link="left_realsense_camera_adapter_tool0"/>
    <child link="left_ur_to_robotiq_link"/>
    <origin rpy="0 0 0" xyz="0 0 0"/>
  </joint>
  <link name="left_ur_to_robotiq_link">
    <visual>
      <origin rpy="0 0 0" xyz="0 0 0"/>
      <geometry>
        <mesh filename="package://robotiq_description/meshes/visual/2f_85/ur_to_robotiq_adapter.dae"/>
      </geometry>
    </visual>
    <collision>
      <origin rpy="0 0 0" xyz="0 0 0"/>
      <geometry>
        <mesh filename="package://robotiq_description/meshes/collision/2f_85/ur_to_robotiq_adapter.stl"/>
      </geometry>
    </collision>
    <inertial>
      <mass value="0.01"/>
      <origin xyz="0 0 0"/>
      <inertia ixx="0.000044" ixy="0.0" ixz="0.0" iyy="0.000027" iyz="0.0" izz="0.000027"/>
    </inertial>
  </link>
  <joint name="left_gripper_side_joint" type="fixed">
    <parent link="left_ur_to_robotiq_link"/>
    <child link="left_gripper_mount_link"/>
    <!-- <origin xyz="0 0 0.011" rpy="0 ${-pi/2} ${pi/2}"/> -->
    <origin rpy="0 0 0" xyz="0 0 0.011"/>
  </joint>
  <link name="left_gripper_mount_link"/>
  <ros2_control name="left_RobotiqGripperHardwareInterface" type="system">
    <!-- Plugins -->
    <hardware>
      <!-- Set use_dummy to true to connect to a dummy driver for testing purposes. -->
      <param name="use_dummy">false</param>
      <plugin>robotiq_driver/RobotiqGripperHardwareInterface</plugin>
      <!--<plugin>mock_components/GenericSystem</plugin>-->
      <param name="gripper_closed_position">0.7929</param>
      <!--      <param name="COM_port">/tmp/ttyUR</param>-->
      <param name="COM_port">/dev/ttyUSB0</param>
      <param name="gripper_speed_multiplier">1.0</param>
      <param name="gripper_force_multiplier">0.5</param>
    </hardware>
    <!-- Joint interfaces -->
    <!-- With Ignition or Hardware, they handle mimic joints, so we only need this command interface activated -->
    <joint name="left_robotiq_85_left_knuckle_joint">
      <command_interface name="position"/>
      <state_interface name="position">
        <param name="initial_value">0.7929</param>
      </state_interface>
      <state_interface name="velocity"/>
    </joint>
    <gpio name="reactivate_gripper">
      <command_interface name="reactivate_gripper_cmd"/>
      <command_interface name="reactivate_gripper_response"/>
    </gpio>
  </ros2_control>
  <link name="left_robotiq_85_base_link">
    <visual>
      <geometry>
        <mesh filename="package://robotiq_description/meshes/visual/2f_85/robotiq_base.dae"/>
      </geometry>
    </visual>
    <collision>
      <geometry>
        <mesh filename="package://robotiq_description/meshes/collision/2f_85/robotiq_base.stl"/>
      </geometry>
    </collision>
    <inertial>
      <origin rpy="0 0 0" xyz="0.0 2.274e-05 0.03232288"/>
      <mass value="6.6320197e-01"/>
      <inertia ixx="5.1617816e-04" ixy="2.936e-8" ixz="0.0" iyy="5.8802208e-04" iyz="-3.2296e-7" izz="3.9462776e-04"/>
    </inertial>
  </link>
  <link name="left_robotiq_85_left_knuckle_link">
    <visual>
      <geometry>
        <mesh filename="package://robotiq_description/meshes/visual/2f_85/left_knuckle.dae"/>
      </geometry>
    </visual>
    <collision>
      <geometry>
        <mesh filename="package://robotiq_description/meshes/collision/2f_85/left_knuckle.stl"/>
      </geometry>
    </collision>
    <inertial>
      <origin rpy="0 0 0" xyz="0.01213197 0.0002 -0.00058647"/>
      <mass value="1.384773208e-02"/>
      <inertia ixx="3.5232e-7" ixy="0.0" ixz="1.1744e-7" iyy="2.31944e-6" iyz="0" izz="2.23136e-6"/>
    </inertial>
  </link>
  <link name="left_robotiq_85_right_knuckle_link">
    <visual>
      <geometry>
        <mesh filename="package://robotiq_description/meshes/visual/2f_85/right_knuckle.dae"/>
      </geometry>
    </visual>
    <collision>
      <geometry>
        <mesh filename="package://robotiq_description/meshes/collision/2f_85/right_knuckle.stl"/>
      </geometry>
    </collision>
    <inertial>
      <origin rpy="0 0 0" xyz="-0.01213197 0.0002 -0.00058647"/>
      <mass value="1.384773208e-02"/>
      <inertia ixx="3.5232e-7" ixy="0.0" ixz="-1.1744e-7" iyy="2.31944e-6" iyz="0.0" izz="2.23136e-6"/>
    </inertial>
  </link>
  <link name="left_robotiq_85_left_finger_link">
    <visual>
      <geometry>
        <mesh filename="package://robotiq_description/meshes/visual/2f_85/left_finger.dae"/>
      </geometry>
    </visual>
    <collision>
      <geometry>
        <mesh filename="package://robotiq_description/meshes/collision/2f_85/left_finger.stl"/>
      </geometry>
    </collision>
    <inertial>
      <origin rpy="0 0 0" xyz="0.00346899 -0.00079447 0.01867121"/>
      <mass value="4.260376752e-02"/>
      <inertia ixx="1.385792000000000e-05" ixy="0.0" ixz="-2.17264e-06" iyy="1.183208e-05" iyz="0.0" izz="5.19672e-06"/>
    </inertial>
  </link>
  <link name="left_robotiq_85_right_finger_link">
    <visual>
      <geometry>
        <mesh filename="package://robotiq_description/meshes/visual/2f_85/right_finger.dae"/>
      </geometry>
    </visual>
    <collision>
      <geometry>
        <mesh filename="package://robotiq_description/meshes/collision/2f_85/right_finger.stl"/>
      </geometry>
    </collision>
    <inertial>
      <origin rpy="0 0 0" xyz="-0.00346899 -5.53e-06 0.01867121"/>
      <mass value="4.260376752000000e-02"/>
      <inertia ixx="1.385792e-05" ixy="0.0" ixz="2.17264e-06" iyy="1.183208e-05" iyz="0.0" izz="5.19672e-06"/>
    </inertial>
  </link>
  <link name="left_robotiq_85_left_inner_knuckle_link">
    <visual>
      <geometry>
        <mesh filename="package://robotiq_description/meshes/visual/2f_85/left_inner_knuckle.dae"/>
      </geometry>
    </visual>
    <collision>
      <geometry>
        <mesh filename="package://robotiq_description/meshes/collision/2f_85/left_inner_knuckle.stl"/>
      </geometry>
    </collision>
    <inertial>
      <origin rpy="0 0 0" xyz="0.01897699 0.00015001 0.02247101"/>
      <mass value="2.969376448e-02"/>
      <inertia ixx="9.57136e-06" ixy="0.0" ixz="-3.93424e-06" iyy="8.69056e-06" iyz="0.0" izz="8.19144e-06"/>
    </inertial>
  </link>
  <link name="left_robotiq_85_right_inner_knuckle_link">
    <visual>
      <geometry>
        <mesh filename="package://robotiq_description/meshes/visual/2f_85/right_inner_knuckle.dae"/>
      </geometry>
    </visual>
    <collision>
      <geometry>
        <mesh filename="package://robotiq_description/meshes/collision/2f_85/right_inner_knuckle.stl"/>
      </geometry>
    </collision>
    <inertial>
      <origin rpy="0 0 0" xyz="-0.01926824 5.001e-05 0.02222178"/>
      <mass value="2.969376448e-02"/>
      <inertia ixx="9.42456e-06" ixy="0.0" ixz="3.9636e-06" iyy="8.69056e-06" iyz="0.0" izz="8.33824e-06"/>
    </inertial>
  </link>
  <link name="left_robotiq_85_left_finger_tip_link">
    <visual>
      <geometry>
        <mesh filename="package://robotiq_description/meshes/visual/2f_85/left_finger_tip.dae"/>
      </geometry>
    </visual>
    <collision>
      <geometry>
        <mesh filename="package://robotiq_description/meshes/collision/2f_85/left_finger_tip.stl"/>
      </geometry>
      <surface>
        <friction>
          <ode>
            <mu1>100000.0</mu1>
            <mu2>100000.0</mu2>
          </ode>
        </friction>
        <contact>
          <ode>
            <kp>1e+5</kp>
            <kd>1</kd>
            <soft_cfm>0</soft_cfm>
            <soft_erp>0.2</soft_erp>
            <minDepth>0.002</minDepth>
            <maxVel>0</maxVel>
          </ode>
        </contact>
      </surface>
    </collision>
    <inertial>
      <origin rpy="0 0 0" xyz="-0.01456706 -0.0008 0.01649701"/>
      <mass value="4.268588744e-02"/>
      <inertia ixx="1.048152e-05" ixy="0.0" ixz="3.5232e-6" iyy="1.197888e-05" iyz="0.0" izz="4.22784e-06"/>
    </inertial>
  </link>
  <link name="left_robotiq_85_right_finger_tip_link">
    <visual>
      <geometry>
        <mesh filename="package://robotiq_description/meshes/visual/2f_85/right_finger_tip.dae"/>
      </geometry>
    </visual>
    <collision>
      <geometry>
        <mesh filename="package://robotiq_description/meshes/collision/2f_85/right_finger_tip.stl"/>
      </geometry>
      <surface>
        <friction>
          <ode>
            <mu1>100000.0</mu1>
            <mu2>100000.0</mu2>
          </ode>
        </friction>
        <contact>
          <ode>
            <kp>1e+5</kp>
            <kd>1</kd>
            <soft_cfm>0</soft_cfm>
            <soft_erp>0.2</soft_erp>
            <minDepth>0.002</minDepth>
            <maxVel>0</maxVel>
          </ode>
        </contact>
      </surface>
    </collision>
    <inertial>
      <origin rpy="0 0 0" xyz="0.01456706 5e-05 0.01649701"/>
      <mass value="4.268588744e-02"/>
      <inertia ixx="1.048152e-05" ixy="0.0" ixz="-3.5232e-06" iyy="1.197888e-05" iyz="0.0" izz="4.22784e-06"/>
    </inertial>
  </link>
  <joint name="left_robotiq_85_base_joint" type="fixed">
    <parent link="left_gripper_mount_link"/>
    <child link="left_robotiq_85_base_link"/>
    <origin rpy="0 0 0" xyz="0 0 0"/>
  </joint>
  <joint name="left_robotiq_85_left_knuckle_joint" type="revolute">
    <parent link="left_robotiq_85_base_link"/>
    <child link="left_robotiq_85_left_knuckle_link"/>
    <axis xyz="0 -1 0"/>
    <origin rpy="0 0 0" xyz="0.03060114 0.0 0.05490452"/>
    <limit effort="50" lower="0.0" upper="0.8" velocity="0.5"/>
  </joint>
  <joint name="left_robotiq_85_right_knuckle_joint" type="revolute">
    <parent link="left_robotiq_85_base_link"/>
    <child link="left_robotiq_85_right_knuckle_link"/>
    <axis xyz="0 -1 0"/>
    <origin rpy="0 0 0" xyz="-0.03060114 0.0 0.05490452"/>
    <limit effort="50" lower="-0.8" upper="0.0" velocity="0.5"/>
    <mimic joint="left_robotiq_85_left_knuckle_joint" multiplier="-1"/>
  </joint>
  <joint name="left_robotiq_85_left_finger_joint" type="fixed">
    <parent link="left_robotiq_85_left_knuckle_link"/>
    <child link="left_robotiq_85_left_finger_link"/>
    <origin rpy="0 0 0" xyz="0.03152616 0.0 -0.00376347"/>
  </joint>
  <joint name="left_robotiq_85_right_finger_joint" type="fixed">
    <parent link="left_robotiq_85_right_knuckle_link"/>
    <child link="left_robotiq_85_right_finger_link"/>
    <origin rpy="0 0 0" xyz="-0.03152616 0.0 -0.00376347"/>
  </joint>
  <joint name="left_robotiq_85_left_inner_knuckle_joint" type="continuous">
    <parent link="left_robotiq_85_base_link"/>
    <child link="left_robotiq_85_left_inner_knuckle_link"/>
    <axis xyz="0 -1 0"/>
    <origin rpy="0 0 0" xyz="0.0127 0.0 0.06142"/>
    <mimic joint="left_robotiq_85_left_knuckle_joint"/>
  </joint>
  <joint name="left_robotiq_85_right_inner_knuckle_joint" type="continuous">
    <parent link="left_robotiq_85_base_link"/>
    <child link="left_robotiq_85_right_inner_knuckle_link"/>
    <axis xyz="0 -1 0"/>
    <origin rpy="0 0 0" xyz="-0.0127 0.0 0.06142"/>
    <mimic joint="left_robotiq_85_left_knuckle_joint" multiplier="-1"/>
  </joint>
  <joint name="left_robotiq_85_left_finger_tip_joint" type="continuous">
    <parent link="left_robotiq_85_left_finger_link"/>
    <child link="left_robotiq_85_left_finger_tip_link"/>
    <axis xyz="0 -1 0"/>
    <origin rpy="0 0 0" xyz="0.00563134 0.0 0.04718515"/>
    <mimic joint="left_robotiq_85_left_knuckle_joint" multiplier="-1"/>
  </joint>
  <joint name="left_robotiq_85_right_finger_tip_joint" type="continuous">
    <parent link="left_robotiq_85_right_finger_link"/>
    <child link="left_robotiq_85_right_finger_tip_link"/>
    <axis xyz="0 -1 0"/>
    <origin rpy="0 0 0" xyz="-0.00563134 0.0 0.04718515"/>
    <mimic joint="left_robotiq_85_left_knuckle_joint"/>
  </joint>
  <!-- This link aligns the axes of the grasp frame to our required convention for motion planning tasks. -->
  <link name="left_grasp_link"/>
  <joint name="left_grasp_link_joint" type="fixed">
    <parent link="left_robotiq_85_base_link"/>
    <child link="left_grasp_link"/>
    <origin rpy="0.0 0.0 3.141592653589793" xyz="0.0 0.0 0.134"/>
  </joint>
  <!-- Link -->
  <link name="lift_right_plate_link">
    <visual>
      <origin rpy="0.0 0.0 0.0" xyz="0.0 0.0 0.0"/>
      <geometry>
        <mesh filename="package://ewellix_description/meshes/tlt500/plate.stl"/>
      </geometry>
      <material name="LightGrey">
        <color rgba="0.7 0.7 0.7 1.0"/>
      </material>
    </visual>
    <collision>
      <origin rpy="0.0 0.0 0.0" xyz="0.0 0.0 0.0075"/>
      <geometry>
        <box size="0.2 0.22 0.015"/>
      </geometry>
      <material name="LightGrey">
        <color rgba="0.7 0.7 0.7 1.0"/>
      </material>
    </collision>
    <inertial>
      <mass value="1.0"/>
      <origin rpy="0.0 0.0 0.0" xyz="0.0 0.0 0.0075"/>
      <inertia ixx="0.004052083333333333" ixy="0.0" ixz="0.0" iyy="0.003352083333333334" iyz="0.0" izz="0.007366666666666667"/>
    </inertial>
  </link>
  <joint name="lift_right_plate_joint" type="fixed">
    <child link="lift_right_plate_link"/>
    <parent link="default_mount"/>
    <origin rpy="0.0 0.0 0.0" xyz="0.0 -0.2 0.04"/>
  </joint>
  <joint name="lift_right_base_joint" type="fixed">
    <child link="lift_right_base_link"/>
    <parent link="lift_right_plate_link"/>
    <origin rpy="0.0 0.0 0.0" xyz="0.0 0.0 0.015"/>
  </joint>
  <!-- Link -->
  <link name="lift_right_base_link">
    <visual>
      <origin rpy="0.0 0.0 0.0" xyz="0.0 0.0 -0.0151"/>
      <geometry>
        <mesh filename="package://ewellix_description/meshes/tlt500/long/base.stl"/>
      </geometry>
      <material name="LightGrey">
        <color rgba="0.7 0.7 0.7 1.0"/>
      </material>
    </visual>
    <collision>
      <origin rpy="0.0 0.0 0.0" xyz="0.0 0.0 0.24"/>
      <geometry>
        <box size="0.1654 0.1654 0.48"/>
      </geometry>
      <material name="LightGrey">
        <color rgba="0.7 0.7 0.7 1.0"/>
      </material>
    </collision>
    <inertial>
      <mass value="10.0"/>
      <origin rpy="0.0 0.0 0.0" xyz="0.0 0.0 0.24"/>
      <inertia ixx="0.21479763333333332" ixy="0.0" ixz="0.0" iyy="0.21479763333333332" iyz="0.0" izz="0.04559526666666667"/>
    </inertial>
  </link>
  <!-- Link -->
  <link name="lift_right_lower_link">
    <visual>
      <origin rpy="0.0 0.0 0.0" xyz="0.0 0.0 -0.2721"/>
      <geometry>
        <mesh filename="package://ewellix_description/meshes/tlt500/long/lower.stl"/>
      </geometry>
      <material name="LightGrey">
        <color rgba="0.7 0.7 0.7 1.0"/>
      </material>
    </visual>
    <collision>
      <origin rpy="0.0 0.0 0.0" xyz="0.0 0.0 0.2415"/>
      <geometry>
        <box size="0.1484 0.1484 0.483"/>
      </geometry>
      <material name="LightGrey">
        <color rgba="0.7 0.7 0.7 1.0"/>
      </material>
    </collision>
    <inertial>
      <mass value="10.0"/>
      <origin rpy="0.0 0.0 0.0" xyz="0.0 0.0 0.2415"/>
      <inertia ixx="0.21275963333333334" ixy="0.0" ixz="0.0" iyy="0.21275963333333334" iyz="0.0" izz="0.036704266666666666"/>
    </inertial>
  </link>
  <joint name="lift_right_lower_joint" type="prismatic">
    <child link="lift_right_lower_link"/>
    <parent link="lift_right_base_link"/>
    <origin rpy="0.0 0.0 0.0" xyz="0.0 0.0 0.0"/>
    <limit effort="2000.0" lower="0.0" upper="0.25" velocity="0.025"/>
    <axis xyz="0 0 1"/>
    <dynamics damping="0.01" friction="0.01"/>
    <mimic joint="lift_right_upper_joint" multiplier="0.5"/>
  </joint>
  <!-- Link -->
  <link name="lift_right_upper_link">
    <visual>
      <origin rpy="0.0 0.0 0.0" xyz="0.0 0.0 -0.5151"/>
      <geometry>
        <mesh filename="package://ewellix_description/meshes/tlt500/long/upper.stl"/>
      </geometry>
      <material name="LightGrey">
        <color rgba="0.7 0.7 0.7 1.0"/>
      </material>
    </visual>
    <collision>
      <origin rpy="0.0 0.0 0.0" xyz="0.0 0.0 0.24500000000000005"/>
      <geometry>
        <box size="0.129 0.129 0.4900000000000001"/>
      </geometry>
      <material name="LightGrey">
        <color rgba="0.7 0.7 0.7 1.0"/>
      </material>
    </collision>
    <inertial>
      <mass value="10.0"/>
      <origin rpy="0.0 0.0 0.0" xyz="0.0 0.0 0.24500000000000005"/>
      <inertia ixx="0.21395083333333342" ixy="0.0" ixz="0.0" iyy="0.21395083333333342" iyz="0.0" izz="0.027735"/>
    </inertial>
  </link>
  <joint name="lift_right_upper_joint" type="prismatic">
    <child link="lift_right_upper_link"/>
    <parent link="lift_right_base_link"/>
    <origin rpy="0.0 0.0 0.0" xyz="0.0 0.0 0.025"/>
    <axis xyz="0 0 1"/>
    <limit effort="2000.0" lower="0.0" upper="0.45" velocity="0.025"/>
    <dynamics damping="0.01" friction="0.01"/>
  </joint>
  <!-- Mount -->
  <link name="lift_right_mount"/>
  <joint name="lift_right_mount_joint" type="fixed">
    <child link="lift_right_mount"/>
    <parent link="lift_right_upper_link"/>
    <origin rpy="0.0 0.0 0.0" xyz="0.0 0.0 0.4900000000000001"/>
  </joint>
  <ros2_control name="lift_right_hardware" type="system">
    <hardware>
      <plugin>ewellix_driver/EwellixHardwareInterface</plugin>
      <!--<plugin>mock_components/GenericSystem</plugin>-->
      <!--<param name="port">/dev/clearpath/ewellix_right</param>-->
      <param name="port">/dev/ttyUSB2</param>
      <param name="baud">38400</param>
      <param name="timeout">1000</param>
      <param name="conversion">1600</param>
      <param name="rated_effort">2000</param>
      <param name="tolerance">0.005</param>
    </hardware>
    <joint name="lift_right_upper_joint">
      <command_interface name="position"/>
      <state_interface name="position">
        <param name="initial_value">0.25</param>
      </state_interface>
      <state_interface name="velocity"/>
      <state_interface name="effort"/>
    </joint>
  </ros2_control>
  <ros2_control name="right_arm" type="system">
    <hardware>
      <plugin>ur_robot_driver/URPositionHardwareInterface</plugin>
      <!--<plugin>mock_components/GenericSystem</plugin>-->
      <param name="robot_ip">192.168.131.3</param>
      <param name="script_filename">/opt/ros/humble/share/ur_robot_driver/resources/ros_control.urscript</param>
      <param name="output_recipe_filename">/opt/ros/humble/share/ur_robot_driver/resources/rtde_output_recipe.txt</param>
      <param name="input_recipe_filename">/opt/ros/humble/share/ur_robot_driver/resources/rtde_input_recipe.txt</param>
      <param name="headless_mode">True</param>
      <param name="reverse_port">50005</param>
      <param name="script_sender_port">50006</param>
      <param name="reverse_ip">0.0.0.0</param>
      <param name="script_command_port">50008</param>
      <param name="trajectory_port">50007</param>
      <param name="tf_prefix">right_</param>
      <param name="non_blocking_read">True</param>
      <param name="servoj_gain">2000</param>
      <param name="servoj_lookahead_time">0.03</param>
      <param name="use_tool_communication">True</param>
      <param name="kinematics/hash">calib_12788084448423163542</param>
      <param name="tool_voltage">24</param>
      <param name="tool_parity">0</param>
      <param name="tool_baud_rate">115200</param>
      <param name="tool_stop_bits">1</param>
      <param name="tool_rx_idle_chars">1.5</param>
      <param name="tool_tx_idle_chars">3.5</param>
      <param name="tool_device_name">/tmp/ttyUR</param>
      <param name="tool_tcp_port">54321</param>
      <param name="keep_alive_count">2</param>
    </hardware>
    <joint name="right_shoulder_pan_joint">
      <command_interface name="position"/>
      <command_interface name="velocity"/>
      <state_interface name="position">
        <!-- initial position for the FakeSystem and simulation -->
        <param name="initial_value">0.0</param>
      </state_interface>
      <state_interface name="velocity"/>
      <state_interface name="effort"/>
    </joint>
    <joint name="right_shoulder_lift_joint">
      <command_interface name="position"/>
      <command_interface name="velocity"/>
      <state_interface name="position">
        <!-- initial position for the FakeSystem and simulation -->
        <param name="initial_value">-1.57</param>
      </state_interface>
      <state_interface name="velocity"/>
      <state_interface name="effort"/>
    </joint>
    <joint name="right_elbow_joint">
      <command_interface name="position"/>
      <command_interface name="velocity"/>
      <state_interface name="position">
        <!-- initial position for the FakeSystem and simulation -->
        <param name="initial_value">0.0</param>
      </state_interface>
      <state_interface name="velocity"/>
      <state_interface name="effort"/>
    </joint>
    <joint name="right_wrist_1_joint">
      <command_interface name="position"/>
      <command_interface name="velocity"/>
      <state_interface name="position">
        <!-- initial position for the FakeSystem and simulation -->
        <param name="initial_value">-1.57</param>
      </state_interface>
      <state_interface name="velocity"/>
      <state_interface name="effort"/>
    </joint>
    <joint name="right_wrist_2_joint">
      <command_interface name="position"/>
      <command_interface name="velocity"/>
      <state_interface name="position">
        <!-- initial position for the FakeSystem and simulation -->
        <param name="initial_value">0.0</param>
      </state_interface>
      <state_interface name="velocity"/>
      <state_interface name="effort"/>
    </joint>
    <joint name="right_wrist_3_joint">
      <command_interface name="position"/>
      <command_interface name="velocity"/>
      <state_interface name="position">
        <!-- initial position for the FakeSystem and simulation -->
        <param name="initial_value">0.0</param>
      </state_interface>
      <state_interface name="velocity"/>
      <state_interface name="effort"/>
    </joint>
    <sensor name="right_tcp_fts_sensor">
      <state_interface name="force.x"/>
      <state_interface name="force.y"/>
      <state_interface name="force.z"/>
      <state_interface name="torque.x"/>
      <state_interface name="torque.y"/>
      <state_interface name="torque.z"/>
    </sensor>
    <sensor name="right_tcp_pose">
      <state_interface name="position.x"/>
      <state_interface name="position.y"/>
      <state_interface name="position.z"/>
      <state_interface name="orientation.x"/>
      <state_interface name="orientation.y"/>
      <state_interface name="orientation.z"/>
      <state_interface name="orientation.w"/>
    </sensor>
    <!-- NOTE The following are joints used only for testing with fake hardware and will change in the future -->
    <gpio name="right_speed_scaling">
      <state_interface name="speed_scaling_factor"/>
      <param name="initial_speed_scaling_factor">1</param>
      <command_interface name="target_speed_fraction_cmd"/>
      <command_interface name="target_speed_fraction_async_success"/>
    </gpio>
    <gpio name="right_gpio">
      <command_interface name="standard_digital_output_cmd_0"/>
      <command_interface name="standard_digital_output_cmd_1"/>
      <command_interface name="standard_digital_output_cmd_2"/>
      <command_interface name="standard_digital_output_cmd_3"/>
      <command_interface name="standard_digital_output_cmd_4"/>
      <command_interface name="standard_digital_output_cmd_5"/>
      <command_interface name="standard_digital_output_cmd_6"/>
      <command_interface name="standard_digital_output_cmd_7"/>
      <command_interface name="standard_digital_output_cmd_8"/>
      <command_interface name="standard_digital_output_cmd_9"/>
      <command_interface name="standard_digital_output_cmd_10"/>
      <command_interface name="standard_digital_output_cmd_11"/>
      <command_interface name="standard_digital_output_cmd_12"/>
      <command_interface name="standard_digital_output_cmd_13"/>
      <command_interface name="standard_digital_output_cmd_14"/>
      <command_interface name="standard_digital_output_cmd_15"/>
      <command_interface name="standard_digital_output_cmd_16"/>
      <command_interface name="standard_digital_output_cmd_17"/>
      <command_interface name="standard_analog_output_cmd_0"/>
      <command_interface name="standard_analog_output_cmd_1"/>
      <command_interface name="analog_output_domain_cmd"/>
      <command_interface name="tool_voltage_cmd"/>
      <command_interface name="io_async_success"/>
      <state_interface name="digital_output_0"/>
      <state_interface name="digital_output_1"/>
      <state_interface name="digital_output_2"/>
      <state_interface name="digital_output_3"/>
      <state_interface name="digital_output_4"/>
      <state_interface name="digital_output_5"/>
      <state_interface name="digital_output_6"/>
      <state_interface name="digital_output_7"/>
      <state_interface name="digital_output_8"/>
      <state_interface name="digital_output_9"/>
      <state_interface name="digital_output_10"/>
      <state_interface name="digital_output_11"/>
      <state_interface name="digital_output_12"/>
      <state_interface name="digital_output_13"/>
      <state_interface name="digital_output_14"/>
      <state_interface name="digital_output_15"/>
      <state_interface name="digital_output_16"/>
      <state_interface name="digital_output_17"/>
      <state_interface name="digital_input_0"/>
      <state_interface name="digital_input_1"/>
      <state_interface name="digital_input_2"/>
      <state_interface name="digital_input_3"/>
      <state_interface name="digital_input_4"/>
      <state_interface name="digital_input_5"/>
      <state_interface name="digital_input_6"/>
      <state_interface name="digital_input_7"/>
      <state_interface name="digital_input_8"/>
      <state_interface name="digital_input_9"/>
      <state_interface name="digital_input_10"/>
      <state_interface name="digital_input_11"/>
      <state_interface name="digital_input_12"/>
      <state_interface name="digital_input_13"/>
      <state_interface name="digital_input_14"/>
      <state_interface name="digital_input_15"/>
      <state_interface name="digital_input_16"/>
      <state_interface name="digital_input_17"/>
      <state_interface name="standard_analog_output_0"/>
      <state_interface name="standard_analog_output_1"/>
      <state_interface name="standard_analog_input_0"/>
      <state_interface name="standard_analog_input_1"/>
      <state_interface name="analog_io_type_0"/>
      <state_interface name="analog_io_type_1"/>
      <state_interface name="analog_io_type_2"/>
      <state_interface name="analog_io_type_3"/>
      <state_interface name="tool_mode"/>
      <state_interface name="tool_output_voltage"/>
      <state_interface name="tool_output_current"/>
      <state_interface name="tool_temperature"/>
      <state_interface name="tool_analog_input_0"/>
      <state_interface name="tool_analog_input_1"/>
      <state_interface name="tool_analog_input_type_0"/>
      <state_interface name="tool_analog_input_type_1"/>
      <state_interface name="robot_mode"/>
      <state_interface name="robot_status_bit_0"/>
      <state_interface name="robot_status_bit_1"/>
      <state_interface name="robot_status_bit_2"/>
      <state_interface name="robot_status_bit_3"/>
      <state_interface name="safety_mode"/>
      <state_interface name="safety_status_bit_0"/>
      <state_interface name="safety_status_bit_1"/>
      <state_interface name="safety_status_bit_2"/>
      <state_interface name="safety_status_bit_3"/>
      <state_interface name="safety_status_bit_4"/>
      <state_interface name="safety_status_bit_5"/>
      <state_interface name="safety_status_bit_6"/>
      <state_interface name="safety_status_bit_7"/>
      <state_interface name="safety_status_bit_8"/>
      <state_interface name="safety_status_bit_9"/>
      <state_interface name="safety_status_bit_10"/>
      <state_interface name="program_running"/>
    </gpio>
    <gpio name="right_payload">
      <command_interface name="mass"/>
      <command_interface name="cog.x"/>
      <command_interface name="cog.y"/>
      <command_interface name="cog.z"/>
      <command_interface name="payload_async_success"/>
    </gpio>
    <gpio name="right_resend_robot_program">
      <command_interface name="resend_robot_program_cmd"/>
      <command_interface name="resend_robot_program_async_success"/>
    </gpio>
    <gpio name="right_hand_back_control">
      <command_interface name="hand_back_control_cmd"/>
      <command_interface name="hand_back_control_async_success"/>
    </gpio>
    <gpio name="right_zero_ftsensor">
      <command_interface name="zero_ftsensor_cmd"/>
      <command_interface name="zero_ftsensor_async_success"/>
    </gpio>
    <gpio name="right_system_interface">
      <state_interface name="initialized"/>
    </gpio>
    <gpio name="right_get_robot_software_version">
      <state_interface name="get_version_major"/>
      <state_interface name="get_version_minor"/>
      <state_interface name="get_version_build"/>
      <state_interface name="get_version_bugfix"/>
    </gpio>
  </ros2_control>
  <!-- Add URDF transmission elements (for ros_control) -->
  <!--<xacro:ur_arm_transmission prefix="${prefix}" hw_interface="${transmission_hw_interface}" />-->
  <!-- Placeholder for ros2_control transmission which don't yet exist -->
  <!-- links -  main serial chain -->
  <link name="right_base_link"/>
  <link name="right_base_link_inertia">
    <visual>
      <origin rpy="0 0 3.141592653589793" xyz="0 0 0"/>
      <geometry>
        <mesh filename="package://ur_description/meshes/ur5e/visual/base.dae"/>
      </geometry>
    </visual>
    <collision>
      <origin rpy="0 0 3.141592653589793" xyz="0 0 0"/>
      <geometry>
        <mesh filename="package://ur_description/meshes/ur5e/collision/base.stl"/>
      </geometry>
    </collision>
    <inertial>
      <mass value="4.0"/>
      <origin rpy="0 0 0" xyz="0 0 0"/>
      <inertia ixx="0.00443333156" ixy="0.0" ixz="0.0" iyy="0.00443333156" iyz="0.0" izz="0.0072"/>
    </inertial>
  </link>
  <link name="right_shoulder_link">
    <visual>
      <origin rpy="0 0 3.141592653589793" xyz="0 0 0"/>
      <geometry>
        <mesh filename="package://ur_description/meshes/ur5e/visual/shoulder.dae"/>
      </geometry>
    </visual>
    <collision>
      <origin rpy="0 0 3.141592653589793" xyz="0 0 0"/>
      <geometry>
        <mesh filename="package://ur_description/meshes/ur5e/collision/shoulder.stl"/>
      </geometry>
    </collision>
    <inertial>
      <mass value="3.761"/>
      <origin rpy="0 0 0" xyz="0.0 -0.00193 -0.02561"/>
      <inertia ixx="0.010267499999999999" ixy="0" ixz="0" iyy="0.010267499999999999" iyz="0" izz="0.00666"/>
    </inertial>
  </link>
  <link name="right_upper_arm_link">
    <visual>
      <origin rpy="1.5707963267948966 0 -1.5707963267948966" xyz="0 0 0.138"/>
      <geometry>
        <mesh filename="package://ur_description/meshes/ur5e/visual/upperarm.dae"/>
      </geometry>
    </visual>
    <collision>
      <origin rpy="1.5707963267948966 0 -1.5707963267948966" xyz="0 0 0.138"/>
      <geometry>
        <mesh filename="package://ur_description/meshes/ur5e/collision/upperarm.stl"/>
      </geometry>
    </collision>
    <inertial>
      <mass value="8.058"/>
      <origin rpy="0 1.570796326794897 0" xyz="-0.2125 0.0 0.11336"/>
      <inertia ixx="0.13388583541666665" ixy="0" ixz="0" iyy="0.13388583541666665" iyz="0" izz="0.0151074"/>
    </inertial>
  </link>
  <link name="right_forearm_link">
    <visual>
      <origin rpy="1.5707963267948966 0 -1.5707963267948966" xyz="0 0 0.007"/>
      <geometry>
        <mesh filename="package://ur_description/meshes/ur5e/visual/forearm.dae"/>
      </geometry>
    </visual>
    <collision>
      <origin rpy="1.5707963267948966 0 -1.5707963267948966" xyz="0 0 0.007"/>
      <geometry>
        <mesh filename="package://ur_description/meshes/ur5e/collision/forearm.stl"/>
      </geometry>
    </collision>
    <inertial>
      <mass value="2.846"/>
      <origin rpy="0 1.570796326794897 0" xyz="-0.2422 0.0 0.0265"/>
      <inertia ixx="0.03120936758333333" ixy="0" ixz="0" iyy="0.03120936758333333" iyz="0" izz="0.004095"/>
    </inertial>
  </link>
  <link name="right_wrist_1_link">
    <visual>
      <origin rpy="1.5707963267948966 0 0" xyz="0 0 -0.127"/>
      <geometry>
        <mesh filename="package://ur_description/meshes/ur5e/visual/wrist1.dae"/>
      </geometry>
    </visual>
    <collision>
      <origin rpy="1.5707963267948966 0 0" xyz="0 0 -0.127"/>
      <geometry>
        <mesh filename="package://ur_description/meshes/ur5e/collision/wrist1.stl"/>
      </geometry>
    </collision>
    <inertial>
      <mass value="1.37"/>
      <origin rpy="0 0 0" xyz="0.0 -0.01634 -0.0018"/>
      <inertia ixx="0.0025599" ixy="0" ixz="0" iyy="0.0025599" iyz="0" izz="0.0021942"/>
    </inertial>
  </link>
  <link name="right_wrist_2_link">
    <visual>
      <origin rpy="0 0 0" xyz="0 0 -0.0997"/>
      <geometry>
        <mesh filename="package://ur_description/meshes/ur5e/visual/wrist2.dae"/>
      </geometry>
    </visual>
    <collision>
      <origin rpy="0 0 0" xyz="0 0 -0.0997"/>
      <geometry>
        <mesh filename="package://ur_description/meshes/ur5e/collision/wrist2.stl"/>
      </geometry>
    </collision>
    <inertial>
      <mass value="1.3"/>
      <origin rpy="0 0 0" xyz="0.0 0.01634 -0.0018"/>
      <inertia ixx="0.0025599" ixy="0" ixz="0" iyy="0.0025599" iyz="0" izz="0.0021942"/>
    </inertial>
  </link>
  <link name="right_wrist_3_link">
    <visual>
      <origin rpy="1.5707963267948966 0 0" xyz="0 0 -0.0989"/>
      <geometry>
        <mesh filename="package://ur_description/meshes/ur5e/visual/wrist3.dae"/>
      </geometry>
    </visual>
    <collision>
      <origin rpy="1.5707963267948966 0 0" xyz="0 0 -0.0989"/>
      <geometry>
        <mesh filename="package://ur_description/meshes/ur5e/collision/wrist3.stl"/>
      </geometry>
    </collision>
    <inertial>
      <mass value="0.365"/>
      <origin rpy="0 0 0" xyz="0.0 0.0 -0.001159"/>
      <inertia ixx="9.890414008333333e-05" ixy="0" ixz="0" iyy="9.890414008333333e-05" iyz="0" izz="0.0001321171875"/>
    </inertial>
  </link>
  <!-- base_joint fixes base_link to the environment -->
  <joint name="right_base_joint" type="fixed">
    <origin rpy="0 0 -2.356194490192345" xyz="0 0 0"/>
    <parent link="right_arm_mount_plate_2"/>
    <child link="right_base_link"/>
  </joint>
  <!-- joints - main serial chain -->
  <joint name="right_base_link-base_link_inertia" type="fixed">
    <parent link="right_base_link"/>
    <child link="right_base_link_inertia"/>
    <!-- 'base_link' is REP-103 aligned (so X+ forward), while the internal
           frames of the robot/controller have X+ pointing backwards.
           Use the joint between 'base_link' and 'base_link_inertia' (a dummy
           link/frame) to introduce the necessary rotation over Z (of pi rad).
      -->
    <origin rpy="0 0 3.141592653589793" xyz="0 0 0"/>
  </joint>
  <joint name="right_shoulder_pan_joint" type="revolute">
    <parent link="right_base_link_inertia"/>
    <child link="right_shoulder_link"/>
    <origin rpy="0 0 0" xyz="0 0 0.1625"/>
    <axis xyz="0 0 1"/>
    <limit effort="150.0" lower="-6.283185307179586" upper="6.283185307179586" velocity="3.141592653589793"/>
    <dynamics damping="0" friction="0"/>
  </joint>
  <joint name="right_shoulder_lift_joint" type="revolute">
    <parent link="right_shoulder_link"/>
    <child link="right_upper_arm_link"/>
    <origin rpy="1.570796327 0 0" xyz="0 0 0"/>
    <axis xyz="0 0 1"/>
    <limit effort="150.0" lower="-6.283185307179586" upper="6.283185307179586" velocity="3.141592653589793"/>
    <dynamics damping="0" friction="0"/>
  </joint>
  <joint name="right_elbow_joint" type="revolute">
    <parent link="right_upper_arm_link"/>
    <child link="right_forearm_link"/>
    <origin rpy="0 0 0" xyz="-0.425 0 0"/>
    <axis xyz="0 0 1"/>
    <limit effort="150.0" lower="-3.141592653589793" upper="3.141592653589793" velocity="3.141592653589793"/>
    <dynamics damping="0" friction="0"/>
  </joint>
  <joint name="right_wrist_1_joint" type="revolute">
    <parent link="right_forearm_link"/>
    <child link="right_wrist_1_link"/>
    <origin rpy="0 0 0" xyz="-0.3922 0 0.1333"/>
    <axis xyz="0 0 1"/>
    <limit effort="28.0" lower="-6.283185307179586" upper="6.283185307179586" velocity="3.141592653589793"/>
    <dynamics damping="0" friction="0"/>
  </joint>
  <joint name="right_wrist_2_joint" type="revolute">
    <parent link="right_wrist_1_link"/>
    <child link="right_wrist_2_link"/>
    <origin rpy="1.570796327 0 0" xyz="0 -0.0997 -2.044881182297852e-11"/>
    <axis xyz="0 0 1"/>
    <limit effort="28.0" lower="-6.283185307179586" upper="6.283185307179586" velocity="3.141592653589793"/>
    <dynamics damping="0" friction="0"/>
  </joint>
  <joint name="right_wrist_3_joint" type="revolute">
    <parent link="right_wrist_2_link"/>
    <child link="right_wrist_3_link"/>
    <origin rpy="1.570796326589793 3.141592653589793 3.141592653589793" xyz="0 0.0996 -2.042830148012698e-11"/>
    <axis xyz="0 0 1"/>
    <limit effort="28.0" lower="-6.283185307179586" upper="6.283185307179586" velocity="3.141592653589793"/>
    <dynamics damping="0" friction="0"/>
  </joint>
  <link name="right_ft_frame"/>
  <joint name="right_wrist_3_link-ft_frame" type="fixed">
    <parent link="right_wrist_3_link"/>
    <child link="right_ft_frame"/>
    <origin rpy="0 0 0" xyz="0 0 0"/>
  </joint>
  <!-- ROS-Industrial 'base' frame - base_link to UR 'Base' Coordinates transform -->
  <link name="right_base"/>
  <joint name="right_base_link-base_fixed_joint" type="fixed">
    <!-- Note the rotation over Z of pi radians - as base_link is REP-103
           aligned (i.e., has X+ forward, Y+ left and Z+ up), this is needed
           to correctly align 'base' with the 'Base' coordinate system of
           the UR controller.
      -->
    <origin rpy="0 0 3.141592653589793" xyz="0 0 0"/>
    <parent link="right_base_link"/>
    <child link="right_base"/>
  </joint>
  <!-- ROS-Industrial 'flange' frame - attachment point for EEF models -->
  <link name="right_flange"/>
  <joint name="right_wrist_3-flange" type="fixed">
    <parent link="right_wrist_3_link"/>
    <child link="right_flange"/>
    <origin rpy="0 -1.5707963267948966 -1.5707963267948966" xyz="0 0 0"/>
  </joint>
  <!-- ROS-Industrial 'tool0' frame - all-zeros tool frame -->
  <link name="right_tool0"/>
  <joint name="right_flange-tool0" type="fixed">
    <!-- default toolframe - X+ left, Y+ up, Z+ front -->
    <origin rpy="1.5707963267948966 0 1.5707963267948966" xyz="0 0 0"/>
    <parent link="right_flange"/>
    <child link="right_tool0"/>
  </joint>
  <joint name="right_realsense_camera_adapter_joint" type="fixed">
    <!-- The parent link must be read from the robot model it is attached to. -->
    <parent link="right_tool0"/>
    <child link="right_realsense_camera_adapter_link"/>
    <origin rpy="0 0 0" xyz="0 0 0"/>
  </joint>
  <link name="right_realsense_camera_adapter_link">
    <visual>
      <origin rpy="0 0 0" xyz="0 0 0"/>
      <geometry>
        <mesh filename="package://picknik_accessories/descriptions/brackets/ur_realsense_camera_adapter/picknik_ur5_realsense_camera_adapter_rev2.dae"/>
      </geometry>
    </visual>
    <collision>
      <origin rpy="0 0 0" xyz="0 0 0"/>
      <geometry>
        <mesh filename="package://picknik_accessories/descriptions/brackets/ur_realsense_camera_adapter/picknik_ur5_realsense_camera_adapter_rev2_collision.stl"/>
      </geometry>
    </collision>
  </link>
  <link name="right_realsense_camera_adapter_tool0"/>
  <joint name="right_realsense_camera_adapter_tool0_joint" type="fixed">
    <parent link="right_realsense_camera_adapter_link"/>
    <child link="right_realsense_camera_adapter_tool0"/>
    <origin rpy="0 0 0" xyz="0 0 0.007"/>
  </joint>
  <link name="right_d415_mount_link"/>
  <joint name="right_d415_mount_joint" type="fixed">
    <parent link="right_realsense_camera_adapter_link"/>
    <child link="right_d415_mount_link"/>
    <origin rpy="0 -1.4660765716752369 1.5707963267948966" xyz="0 -0.067 0.0171"/>
  </joint>
  <link name="right_l515_mount_link"/>
  <joint name="right_l515_mount_joint" type="fixed">
    <parent link="right_realsense_camera_adapter_link"/>
    <child link="right_l515_mount_link"/>
    <origin rpy="0 -1.4660765716752369 1.5707963267948966" xyz="0 -0.0406 0.0173"/>
  </joint>
  <!-- camera body, with origin at bottom screw mount -->
  <joint name="right_wrist_mounted_camera_joint" type="fixed">
    <origin rpy="0 0 0" xyz="0 0 0"/>
    <parent link="right_d415_mount_link"/>
    <child link="right_wrist_mounted_camera_bottom_screw_frame"/>
  </joint>
  <link name="right_wrist_mounted_camera_bottom_screw_frame"/>
  <joint name="right_wrist_mounted_camera_link_joint" type="fixed">
    <origin rpy="0 0 0" xyz="0 0.02 0.0115"/>
    <parent link="right_wrist_mounted_camera_bottom_screw_frame"/>
    <child link="right_wrist_mounted_camera_link"/>
  </joint>
  <link name="right_wrist_mounted_camera_link">
    <visual>
      <origin rpy="1.5707963267948966 0 1.5707963267948966" xyz="0.00987 -0.02 0"/>
      <geometry>
        <mesh filename="package://realsense2_description/meshes/d415.stl"/>
      </geometry>
      <material name="rs_aluminum">
        <color rgba="0.5 0.5 0.5 1.0"/>
      </material>
    </visual>
    <collision>
      <origin rpy="0 0 0" xyz="0 -0.02 0"/>
      <geometry>
        <box size="0.02005 0.099 0.023"/>
      </geometry>
    </collision>
    <inertial>
      <mass value="0.072"/>
      <!-- The following are not reliable values, and should not be used for modeling -->
      <origin xyz="0 0 0"/>
      <inertia ixx="0.003881243" ixy="0.0" ixz="0.0" iyy="0.000498940" iyz="0.0" izz="0.003879257"/>
    </inertial>
  </link>
  <!-- camera depth joints and links -->
  <joint name="right_wrist_mounted_camera_depth_joint" type="fixed">
    <origin rpy="0 0 0" xyz="0 0 0"/>
    <parent link="right_wrist_mounted_camera_link"/>
    <child link="right_wrist_mounted_camera_depth_frame"/>
  </joint>
  <link name="right_wrist_mounted_camera_depth_frame"/>
  <joint name="right_wrist_mounted_camera_depth_optical_joint" type="fixed">
    <origin rpy="-1.5707963267948966 0 -1.5707963267948966" xyz="0 0 0"/>
    <parent link="right_wrist_mounted_camera_depth_frame"/>
    <child link="right_wrist_mounted_camera_depth_optical_frame"/>
  </joint>
  <link name="right_wrist_mounted_camera_depth_optical_frame"/>
  <!-- camera left IR joints and links -->
  <joint name="right_wrist_mounted_camera_infra1_joint" type="fixed">
    <origin rpy="0 0 0" xyz="0 0.0 0"/>
    <parent link="right_wrist_mounted_camera_link"/>
    <child link="right_wrist_mounted_camera_infra1_frame"/>
  </joint>
  <link name="right_wrist_mounted_camera_infra1_frame"/>
  <joint name="right_wrist_mounted_camera_infra1_optical_joint" type="fixed">
    <origin rpy="-1.5707963267948966 0 -1.5707963267948966" xyz="0 0 0"/>
    <parent link="right_wrist_mounted_camera_infra1_frame"/>
    <child link="right_wrist_mounted_camera_infra1_optical_frame"/>
  </joint>
  <link name="right_wrist_mounted_camera_infra1_optical_frame"/>
  <!-- camera right IR joints and links -->
  <joint name="right_wrist_mounted_camera_infra2_joint" type="fixed">
    <origin rpy="0 0 0" xyz="0 -0.055 0"/>
    <parent link="right_wrist_mounted_camera_link"/>
    <child link="right_wrist_mounted_camera_infra2_frame"/>
  </joint>
  <link name="right_wrist_mounted_camera_infra2_frame"/>
  <joint name="right_wrist_mounted_camera_infra2_optical_joint" type="fixed">
    <origin rpy="-1.5707963267948966 0 -1.5707963267948966" xyz="0 0 0"/>
    <parent link="right_wrist_mounted_camera_infra2_frame"/>
    <child link="right_wrist_mounted_camera_infra2_optical_frame"/>
  </joint>
  <link name="right_wrist_mounted_camera_infra2_optical_frame"/>
  <!-- camera color joints and links -->
  <joint name="right_wrist_mounted_camera_color_joint" type="fixed">
    <origin rpy="0 0 0" xyz="0 0.015 0"/>
    <parent link="right_wrist_mounted_camera_link"/>
    <child link="right_wrist_mounted_camera_color_frame"/>
  </joint>
  <link name="right_wrist_mounted_camera_color_frame"/>
  <joint name="right_wrist_mounted_camera_color_optical_joint" type="fixed">
    <origin rpy="-1.5707963267948966 0 -1.5707963267948966" xyz="0 0 0"/>
    <parent link="right_wrist_mounted_camera_color_frame"/>
    <child link="right_wrist_mounted_camera_color_optical_frame"/>
  </joint>
  <link name="right_wrist_mounted_camera_color_optical_frame"/>
  <gazebo reference="right_wrist_mounted_camera_color_frame">
    <sensor name="right_wrist_mounted_camera_rgbd_sensor" type="rgbd_camera">
      <camera>
        <horizontal_fov>1.047</horizontal_fov>
        <image>
          <width>640</width>
          <height>480</height>
          <format>RGB_INT8</format>
        </image>
        <clip>
          <near>0.1</near>
          <far>5</far>
        </clip>
        <distortion>
          <k1>0.0</k1>
          <k2>0.0</k2>
          <k3>0.0</k3>
          <p1>0.0</p1>
          <p2>0.0</p2>
          <center>0.5 0.5</center>
        </distortion>
        <lens>
          <intrinsics>
            <fx>554.25469</fx>
            <fy>554.25469</fy>
            <cx>320.5</cx>
            <cy>240.5</cy>
            <s>0</s>
          </intrinsics>
          <!-- These need to match the intrinsics above or
            Ignition will default to different default values -->
          <projection>
            <p_fx>554.25469</p_fx>
            <p_fy>554.25469</p_fy>
            <p_cx>320.5</p_cx>
            <p_cy>240.5</p_cy>
            <tx>0</tx>
            <ty>0</ty>
          </projection>
        </lens>
        <noise>
          <type>gaussian</type>
          <mean>0</mean>
          <stddev>0.00</stddev>
        </noise>
        <depth_camera>
          <clip>
            <near>0.25</near>
            <far>5</far>
          </clip>
        </depth_camera>
        <optical_frame_id>right_wrist_mounted_camera_color_optical_frame</optical_frame_id>
      </camera>
      <ignition_frame_id>right_wrist_mounted_camera_color_frame</ignition_frame_id>
      <always_on>1</always_on>
      <update_rate>6</update_rate>
      <visualize>false</visualize>
      <topic>right_wrist_mounted_camera</topic>
      <enable_metrics>false</enable_metrics>
    </sensor>
  </gazebo>
  <joint name="right_ur_to_robotiq_joint" type="fixed">
    <!-- The parent link must be read from the robot model it is attached to. -->
    <parent link="right_realsense_camera_adapter_tool0"/>
    <child link="right_ur_to_robotiq_link"/>
    <origin rpy="0 0 0" xyz="0 0 0"/>
  </joint>
  <link name="right_ur_to_robotiq_link">
    <visual>
      <origin rpy="0 0 0" xyz="0 0 0"/>
      <geometry>
        <mesh filename="package://robotiq_description/meshes/visual/2f_85/ur_to_robotiq_adapter.dae"/>
      </geometry>
    </visual>
    <collision>
      <origin rpy="0 0 0" xyz="0 0 0"/>
      <geometry>
        <mesh filename="package://robotiq_description/meshes/collision/2f_85/ur_to_robotiq_adapter.stl"/>
      </geometry>
    </collision>
    <inertial>
      <mass value="0.01"/>
      <origin xyz="0 0 0"/>
      <inertia ixx="0.000044" ixy="0.0" ixz="0.0" iyy="0.000027" iyz="0.0" izz="0.000027"/>
    </inertial>
  </link>
  <joint name="right_gripper_side_joint" type="fixed">
    <parent link="right_ur_to_robotiq_link"/>
    <child link="right_gripper_mount_link"/>
    <!-- <origin xyz="0 0 0.011" rpy="0 ${-pi/2} ${pi/2}"/> -->
    <origin rpy="0 0 0" xyz="0 0 0.011"/>
  </joint>
  <link name="right_gripper_mount_link"/>
  <ros2_control name="right_RobotiqGripperHardwareInterface" type="system">
    <!-- Plugins -->
    <hardware>
      <!-- Set use_dummy to true to connect to a dummy driver for testing purposes. -->
      <param name="use_dummy">false</param>
      <plugin>robotiq_driver/RobotiqGripperHardwareInterface</plugin>
      <!--<plugin>mock_components/GenericSystem</plugin>-->
      <param name="gripper_closed_position">0.7929</param>
      <param name="COM_port">/tmp/ttyUR</param>
      <param name="gripper_speed_multiplier">1.0</param>
      <param name="gripper_force_multiplier">0.5</param>
    </hardware>
    <!-- Joint interfaces -->
    <!-- With Ignition or Hardware, they handle mimic joints, so we only need this command interface activated -->
    <joint name="right_robotiq_85_left_knuckle_joint">
      <command_interface name="position"/>
      <state_interface name="position">
        <param name="initial_value">0.7929</param>
      </state_interface>
      <state_interface name="velocity"/>
    </joint>
    <gpio name="reactivate_gripper">
      <command_interface name="reactivate_gripper_cmd"/>
      <command_interface name="reactivate_gripper_response"/>
    </gpio>
  </ros2_control>
  <link name="right_robotiq_85_base_link">
    <visual>
      <geometry>
        <mesh filename="package://robotiq_description/meshes/visual/2f_85/robotiq_base.dae"/>
      </geometry>
    </visual>
    <collision>
      <geometry>
        <mesh filename="package://robotiq_description/meshes/collision/2f_85/robotiq_base.stl"/>
      </geometry>
    </collision>
    <inertial>
      <origin rpy="0 0 0" xyz="0.0 2.274e-05 0.03232288"/>
      <mass value="6.6320197e-01"/>
      <inertia ixx="5.1617816e-04" ixy="2.936e-8" ixz="0.0" iyy="5.8802208e-04" iyz="-3.2296e-7" izz="3.9462776e-04"/>
    </inertial>
  </link>
  <link name="right_robotiq_85_left_knuckle_link">
    <visual>
      <geometry>
        <mesh filename="package://robotiq_description/meshes/visual/2f_85/left_knuckle.dae"/>
      </geometry>
    </visual>
    <collision>
      <geometry>
        <mesh filename="package://robotiq_description/meshes/collision/2f_85/left_knuckle.stl"/>
      </geometry>
    </collision>
    <inertial>
      <origin rpy="0 0 0" xyz="0.01213197 0.0002 -0.00058647"/>
      <mass value="1.384773208e-02"/>
      <inertia ixx="3.5232e-7" ixy="0.0" ixz="1.1744e-7" iyy="2.31944e-6" iyz="0" izz="2.23136e-6"/>
    </inertial>
  </link>
  <link name="right_robotiq_85_right_knuckle_link">
    <visual>
      <geometry>
        <mesh filename="package://robotiq_description/meshes/visual/2f_85/right_knuckle.dae"/>
      </geometry>
    </visual>
    <collision>
      <geometry>
        <mesh filename="package://robotiq_description/meshes/collision/2f_85/right_knuckle.stl"/>
      </geometry>
    </collision>
    <inertial>
      <origin rpy="0 0 0" xyz="-0.01213197 0.0002 -0.00058647"/>
      <mass value="1.384773208e-02"/>
      <inertia ixx="3.5232e-7" ixy="0.0" ixz="-1.1744e-7" iyy="2.31944e-6" iyz="0.0" izz="2.23136e-6"/>
    </inertial>
  </link>
  <link name="right_robotiq_85_left_finger_link">
    <visual>
      <geometry>
        <mesh filename="package://robotiq_description/meshes/visual/2f_85/left_finger.dae"/>
      </geometry>
    </visual>
    <collision>
      <geometry>
        <mesh filename="package://robotiq_description/meshes/collision/2f_85/left_finger.stl"/>
      </geometry>
    </collision>
    <inertial>
      <origin rpy="0 0 0" xyz="0.00346899 -0.00079447 0.01867121"/>
      <mass value="4.260376752e-02"/>
      <inertia ixx="1.385792000000000e-05" ixy="0.0" ixz="-2.17264e-06" iyy="1.183208e-05" iyz="0.0" izz="5.19672e-06"/>
    </inertial>
  </link>
  <link name="right_robotiq_85_right_finger_link">
    <visual>
      <geometry>
        <mesh filename="package://robotiq_description/meshes/visual/2f_85/right_finger.dae"/>
      </geometry>
    </visual>
    <collision>
      <geometry>
        <mesh filename="package://robotiq_description/meshes/collision/2f_85/right_finger.stl"/>
      </geometry>
    </collision>
    <inertial>
      <origin rpy="0 0 0" xyz="-0.00346899 -5.53e-06 0.01867121"/>
      <mass value="4.260376752000000e-02"/>
      <inertia ixx="1.385792e-05" ixy="0.0" ixz="2.17264e-06" iyy="1.183208e-05" iyz="0.0" izz="5.19672e-06"/>
    </inertial>
  </link>
  <link name="right_robotiq_85_left_inner_knuckle_link">
    <visual>
      <geometry>
        <mesh filename="package://robotiq_description/meshes/visual/2f_85/left_inner_knuckle.dae"/>
      </geometry>
    </visual>
    <collision>
      <geometry>
        <mesh filename="package://robotiq_description/meshes/collision/2f_85/left_inner_knuckle.stl"/>
      </geometry>
    </collision>
    <inertial>
      <origin rpy="0 0 0" xyz="0.01897699 0.00015001 0.02247101"/>
      <mass value="2.969376448e-02"/>
      <inertia ixx="9.57136e-06" ixy="0.0" ixz="-3.93424e-06" iyy="8.69056e-06" iyz="0.0" izz="8.19144e-06"/>
    </inertial>
  </link>
  <link name="right_robotiq_85_right_inner_knuckle_link">
    <visual>
      <geometry>
        <mesh filename="package://robotiq_description/meshes/visual/2f_85/right_inner_knuckle.dae"/>
      </geometry>
    </visual>
    <collision>
      <geometry>
        <mesh filename="package://robotiq_description/meshes/collision/2f_85/right_inner_knuckle.stl"/>
      </geometry>
    </collision>
    <inertial>
      <origin rpy="0 0 0" xyz="-0.01926824 5.001e-05 0.02222178"/>
      <mass value="2.969376448e-02"/>
      <inertia ixx="9.42456e-06" ixy="0.0" ixz="3.9636e-06" iyy="8.69056e-06" iyz="0.0" izz="8.33824e-06"/>
    </inertial>
  </link>
  <link name="right_robotiq_85_left_finger_tip_link">
    <visual>
      <geometry>
        <mesh filename="package://robotiq_description/meshes/visual/2f_85/left_finger_tip.dae"/>
      </geometry>
    </visual>
    <collision>
      <geometry>
        <mesh filename="package://robotiq_description/meshes/collision/2f_85/left_finger_tip.stl"/>
      </geometry>
      <surface>
        <friction>
          <ode>
            <mu1>100000.0</mu1>
            <mu2>100000.0</mu2>
          </ode>
        </friction>
        <contact>
          <ode>
            <kp>1e+5</kp>
            <kd>1</kd>
            <soft_cfm>0</soft_cfm>
            <soft_erp>0.2</soft_erp>
            <minDepth>0.002</minDepth>
            <maxVel>0</maxVel>
          </ode>
        </contact>
      </surface>
    </collision>
    <inertial>
      <origin rpy="0 0 0" xyz="-0.01456706 -0.0008 0.01649701"/>
      <mass value="4.268588744e-02"/>
      <inertia ixx="1.048152e-05" ixy="0.0" ixz="3.5232e-6" iyy="1.197888e-05" iyz="0.0" izz="4.22784e-06"/>
    </inertial>
  </link>
  <link name="right_robotiq_85_right_finger_tip_link">
    <visual>
      <geometry>
        <mesh filename="package://robotiq_description/meshes/visual/2f_85/right_finger_tip.dae"/>
      </geometry>
    </visual>
    <collision>
      <geometry>
        <mesh filename="package://robotiq_description/meshes/collision/2f_85/right_finger_tip.stl"/>
      </geometry>
      <surface>
        <friction>
          <ode>
            <mu1>100000.0</mu1>
            <mu2>100000.0</mu2>
          </ode>
        </friction>
        <contact>
          <ode>
            <kp>1e+5</kp>
            <kd>1</kd>
            <soft_cfm>0</soft_cfm>
            <soft_erp>0.2</soft_erp>
            <minDepth>0.002</minDepth>
            <maxVel>0</maxVel>
          </ode>
        </contact>
      </surface>
    </collision>
    <inertial>
      <origin rpy="0 0 0" xyz="0.01456706 5e-05 0.01649701"/>
      <mass value="4.268588744e-02"/>
      <inertia ixx="1.048152e-05" ixy="0.0" ixz="-3.5232e-06" iyy="1.197888e-05" iyz="0.0" izz="4.22784e-06"/>
    </inertial>
  </link>
  <joint name="right_robotiq_85_base_joint" type="fixed">
    <parent link="right_gripper_mount_link"/>
    <child link="right_robotiq_85_base_link"/>
    <origin rpy="0 0 0" xyz="0 0 0"/>
  </joint>
  <joint name="right_robotiq_85_left_knuckle_joint" type="revolute">
    <parent link="right_robotiq_85_base_link"/>
    <child link="right_robotiq_85_left_knuckle_link"/>
    <axis xyz="0 -1 0"/>
    <origin rpy="0 0 0" xyz="0.03060114 0.0 0.05490452"/>
    <limit effort="50" lower="0.0" upper="0.8" velocity="0.5"/>
  </joint>
  <joint name="right_robotiq_85_right_knuckle_joint" type="revolute">
    <parent link="right_robotiq_85_base_link"/>
    <child link="right_robotiq_85_right_knuckle_link"/>
    <axis xyz="0 -1 0"/>
    <origin rpy="0 0 0" xyz="-0.03060114 0.0 0.05490452"/>
    <limit effort="50" lower="-0.8" upper="0.0" velocity="0.5"/>
    <mimic joint="right_robotiq_85_left_knuckle_joint" multiplier="-1"/>
  </joint>
  <joint name="right_robotiq_85_left_finger_joint" type="fixed">
    <parent link="right_robotiq_85_left_knuckle_link"/>
    <child link="right_robotiq_85_left_finger_link"/>
    <origin rpy="0 0 0" xyz="0.03152616 0.0 -0.00376347"/>
  </joint>
  <joint name="right_robotiq_85_right_finger_joint" type="fixed">
    <parent link="right_robotiq_85_right_knuckle_link"/>
    <child link="right_robotiq_85_right_finger_link"/>
    <origin rpy="0 0 0" xyz="-0.03152616 0.0 -0.00376347"/>
  </joint>
  <joint name="right_robotiq_85_left_inner_knuckle_joint" type="continuous">
    <parent link="right_robotiq_85_base_link"/>
    <child link="right_robotiq_85_left_inner_knuckle_link"/>
    <axis xyz="0 -1 0"/>
    <origin rpy="0 0 0" xyz="0.0127 0.0 0.06142"/>
    <mimic joint="right_robotiq_85_left_knuckle_joint"/>
  </joint>
  <joint name="right_robotiq_85_right_inner_knuckle_joint" type="continuous">
    <parent link="right_robotiq_85_base_link"/>
    <child link="right_robotiq_85_right_inner_knuckle_link"/>
    <axis xyz="0 -1 0"/>
    <origin rpy="0 0 0" xyz="-0.0127 0.0 0.06142"/>
    <mimic joint="right_robotiq_85_left_knuckle_joint" multiplier="-1"/>
  </joint>
  <joint name="right_robotiq_85_left_finger_tip_joint" type="continuous">
    <parent link="right_robotiq_85_left_finger_link"/>
    <child link="right_robotiq_85_left_finger_tip_link"/>
    <axis xyz="0 -1 0"/>
    <origin rpy="0 0 0" xyz="0.00563134 0.0 0.04718515"/>
    <mimic joint="right_robotiq_85_left_knuckle_joint" multiplier="-1"/>
  </joint>
  <joint name="right_robotiq_85_right_finger_tip_joint" type="continuous">
    <parent link="right_robotiq_85_right_finger_link"/>
    <child link="right_robotiq_85_right_finger_tip_link"/>
    <axis xyz="0 -1 0"/>
    <origin rpy="0 0 0" xyz="-0.00563134 0.0 0.04718515"/>
    <mimic joint="right_robotiq_85_left_knuckle_joint"/>
  </joint>
  <!-- This link aligns the axes of the grasp frame to our required convention for motion planning tasks. -->
  <link name="right_grasp_link"/>
  <joint name="right_grasp_link_joint" type="fixed">
    <parent link="right_robotiq_85_base_link"/>
    <child link="right_grasp_link"/>
    <origin rpy="0.0 0.0 3.141592653589793" xyz="0.0 0.0 0.134"/>
  </joint>
  <!-- Mounting rails for lifts -->
  <link name="lift_rails">
    <visual>
      <geometry>
        <mesh filename="package://dual_arm_mobile_hw/description/meshes/lift_rails.STL"/>
      </geometry>
      <material name="clearpath_dark_grey"/>
    </visual>
    <collision>
      <origin xyz="0.000 -0.000 0.020"/>
      <geometry>
        <box size="0.220 0.730 0.040"/>
      </geometry>
    </collision>
  </link>
  <joint name="lift_rails_joint" type="fixed">
    <parent link="default_mount"/>
    <child link="lift_rails"/>
    <origin rpy="0 0 0" xyz="0 0 0"/>
  </joint>
  <!-- Rear shelf -->
  <link name="rear_shelf">
    <visual>
      <geometry>
        <mesh filename="package://dual_arm_mobile_hw/description/meshes/shelf.STL"/>
      </geometry>
      <material name="clearpath_dark_grey"/>
    </visual>
    <collision>
      <origin xyz="-0.289 0.000 0.113"/>
      <geometry>
        <box size="0.379 0.790 0.226"/>
      </geometry>
    </collision>
  </link>
  <joint name="rear_shelf_joint" type="fixed">
    <parent link="default_mount"/>
    <child link="rear_shelf"/>
    <origin rpy="0 0 0" xyz="0 0 0"/>
  </joint>
  <!-- Front shelf -->
  <link name="front_shelf">
    <visual>
      <geometry>
        <mesh filename="package://dual_arm_mobile_hw/description/meshes/shelf.STL"/>
      </geometry>
      <material name="clearpath_dark_grey"/>
    </visual>
    <collision>
      <origin xyz="-0.289 0.000 0.113"/>
      <geometry>
        <box size="0.379 0.790 0.226"/>
      </geometry>
    </collision>
  </link>
  <joint name="front_shelf_joint" type="fixed">
    <parent link="default_mount"/>
    <child link="front_shelf"/>
    <origin rpy="0 0 3.141592653589793" xyz="0 0 0"/>
  </joint>
  <!-- Monitor hinge base -->
  <link name="monitor_hinge_base">
    <visual>
      <geometry>
        <mesh filename="package://dual_arm_mobile_hw/description/meshes/monitor_hinge_base.STL"/>
      </geometry>
      <material name="clearpath_dark_grey"/>
    </visual>
    <collision>
      <origin xyz="0.000 0.000 -0.003"/>
      <geometry>
        <box size="0.040 0.450 0.036"/>
      </geometry>
    </collision>
  </link>
  <joint name="monitor_hinge_base_joint" type="fixed">
    <parent link="default_mount"/>
    <child link="monitor_hinge_base"/>
    <origin rpy="0 0 0" xyz="-0.4 0 0.24635"/>
  </joint>
  <!-- Monitor hinge top -->
  <link name="monitor_hinge_top">
    <visual>
      <geometry>
        <mesh filename="package://dual_arm_mobile_hw/description/meshes/monitor_hinge_top.STL"/>
      </geometry>
      <material name="clearpath_dark_grey"/>
    </visual>
    <collision>
      <origin xyz="-0.013 0.000 0.000"/>
      <geometry>
        <box size="0.055 0.450 0.040"/>
      </geometry>
    </collision>
  </link>
  <joint name="monitor_hinge_top_joint" type="fixed">
    <parent link="monitor_hinge_base"/>
    <child link="monitor_hinge_top"/>
    <origin rpy="0 0.74 0" xyz="0 0 0"/>
  </joint>
  <!-- Left monitor -->
  <link name="left_monitor">
    <visual>
      <geometry>
        <mesh filename="package://dual_arm_mobile_hw/description/meshes/monitor.STL"/>
      </geometry>
      <material name="clearpath_dark_grey"/>
    </visual>
    <collision>
      <origin xyz="-0.015 0.000 -0.008"/>
      <geometry>
        <box size="0.071 0.260 0.176"/>
      </geometry>
    </collision>
  </link>
  <joint name="left_monitor_joint" type="fixed">
    <parent link="monitor_hinge_top"/>
    <child link="left_monitor"/>
    <origin rpy="0 0 0" xyz="-0.04 0.18 0.01"/>
  </joint>
  <!-- Right monitor -->
  <link name="right_monitor">
    <visual>
      <geometry>
        <mesh filename="package://dual_arm_mobile_hw/description/meshes/monitor.STL"/>
      </geometry>
      <material name="clearpath_dark_grey"/>
    </visual>
    <collision>
      <origin xyz="-0.015 0.000 -0.008"/>
      <geometry>
        <box size="0.071 0.260 0.176"/>
      </geometry>
    </collision>
  </link>
  <joint name="right_monitor_joint" type="fixed">
    <parent link="monitor_hinge_top"/>
    <child link="right_monitor"/>
    <origin rpy="0 0 0" xyz="-0.04 -0.18 0.01"/>
  </joint>
  <!-- Rear UR Control Box -->
  <link name="rear_ur_control_box">
    <visual>
      <geometry>
        <mesh filename="package://dual_arm_mobile_hw/description/meshes/ur_control_box.STL"/>
      </geometry>
      <material name="clearpath_aluminum"/>
    </visual>
    <collision>
      <origin xyz="0.090 -0.107 0.098"/>
      <geometry>
        <box size="0.199 0.502 0.195"/>
      </geometry>
    </collision>
  </link>
  <joint name="rear_ur_control_box_joint" type="fixed">
    <parent link="default_mount"/>
    <child link="rear_ur_control_box"/>
    <origin rpy="0 0 0" xyz="-0.44274 0.13 0"/>
  </joint>
  <!-- Front UR Control Box -->
  <link name="front_ur_control_box">
    <visual>
      <geometry>
        <mesh filename="package://dual_arm_mobile_hw/description/meshes/ur_control_box.STL"/>
      </geometry>
      <material name="clearpath_aluminum"/>
    </visual>
    <collision>
      <origin xyz="0.090 -0.107 0.098"/>
      <geometry>
        <box size="0.199 0.502 0.195"/>
      </geometry>
    </collision>
  </link>
  <joint name="front_ur_control_box_joint" type="fixed">
    <parent link="default_mount"/>
    <child link="front_ur_control_box"/>
    <origin rpy="0 0 3.141592653589793" xyz="0.44274 -0.13 0"/>
  </joint>
  <!-- Rear Ewellix SCU -->
  <link name="rear_scu">
    <visual>
      <geometry>
        <mesh filename="package://dual_arm_mobile_hw/description/meshes/scu.STL"/>
      </geometry>
      <material name="clearpath_aluminum"/>
    </visual>
    <collision>
      <origin xyz="0.000 0.002 0.043"/>
      <geometry>
        <box size="0.140 0.365 0.087"/>
      </geometry>
    </collision>
  </link>
  <joint name="rear_scu_joint" type="fixed">
    <parent link="default_mount"/>
    <child link="rear_scu"/>
    <origin rpy="0 0 0" xyz="-0.18187 0 0"/>
  </joint>
  <!-- Front Ewellix SCU -->
  <link name="front_scu">
    <visual>
      <geometry>
        <mesh filename="package://dual_arm_mobile_hw/description/meshes/scu.STL"/>
      </geometry>
      <material name="clearpath_aluminum"/>
    </visual>
    <collision>
      <origin xyz="0.000 0.002 0.043"/>
      <geometry>
        <box size="0.140 0.365 0.087"/>
      </geometry>
    </collision>
  </link>
  <joint name="front_scu_joint" type="fixed">
    <parent link="default_mount"/>
    <child link="front_scu"/>
    <origin rpy="0 0 3.141592653589793" xyz="0.18187 0 0"/>
  </joint>
  <!-- Autec wireless e-stop MVRCAN receiver -->
  <link name="autec_receiver">
    <visual>
      <geometry>
        <mesh filename="package://dual_arm_mobile_hw/description/meshes/autec_receiver.STL"/>
      </geometry>
      <material name="clearpath_yellow"/>
    </visual>
    <collision>
      <origin xyz="0.008 0.000 0.031"/>
      <geometry>
        <box size="0.255 0.142 0.062"/>
      </geometry>
    </collision>
  </link>
  <joint name="autec_receiver_joint" type="fixed">
    <parent link="default_mount"/>
    <child link="autec_receiver"/>
    <origin rpy="0 0 0" xyz="-0.26 -0.29909 0"/>
  </joint>
  <!-- Right wifi antenna -->
  <link name="right_wifi_antenna">
    <visual>
      <geometry>
        <mesh filename="package://dual_arm_mobile_hw/description/meshes/wifi_antenna.STL"/>
      </geometry>
      <material name="clearpath_dark_grey"/>
    </visual>
    <collision>
      <origin xyz="-0.003 0.000 0.089"/>
      <geometry>
        <cylinder length="0.229" radius="0.033"/>
      </geometry>
    </collision>
  </link>
  <joint name="right_wifi_antenna_joint" type="fixed">
    <parent link="default_mount"/>
    <child link="right_wifi_antenna"/>
    <origin rpy="0 0 0" xyz="-0.086 -0.384 0.22"/>
  </joint>
  <!-- Left wifi antenna -->
  <link name="left_wifi_antenna">
    <visual>
      <geometry>
        <mesh filename="package://dual_arm_mobile_hw/description/meshes/wifi_antenna.STL"/>
      </geometry>
      <material name="clearpath_dark_grey"/>
    </visual>
    <collision>
      <origin xyz="-0.003 0.000 0.089"/>
      <geometry>
        <cylinder length="0.229" radius="0.033"/>
      </geometry>
    </collision>
  </link>
  <joint name="left_wifi_antenna_joint" type="fixed">
    <parent link="default_mount"/>
    <child link="left_wifi_antenna"/>
    <origin rpy="0 0 0" xyz="-0.086 0.384 0.22"/>
  </joint>
  <!-- Autec wireless e-stop antenna -->
  <link name="autec_antenna">
    <visual>
      <geometry>
        <mesh filename="package://dual_arm_mobile_hw/description/meshes/autec_antenna.STL"/>
      </geometry>
      <material name="clearpath_dark_grey"/>
    </visual>
    <collision>
      <origin xyz="0.002 0.000 0.049"/>
      <geometry>
        <cylinder length="0.147" radius="0.037"/>
      </geometry>
    </collision>
  </link>
  <joint name="autec_antenna_joint" type="fixed">
    <parent link="default_mount"/>
    <child link="autec_antenna"/>
    <origin rpy="0 0 0" xyz="0.0845 -0.384 0.22"/>
  </joint>
  <!-- Left arm mount plate -->
  <link name="left_arm_mount_plate">
    <visual>
      <geometry>
        <mesh filename="package://dual_arm_mobile_hw/description/meshes/arm_mount.STL"/>
      </geometry>
      <material name="clearpath_dark_grey"/>
    </visual>
    <collision>
      <geometry>
        <mesh filename="package://dual_arm_mobile_hw/description/meshes/arm_mount_collision.STL"/>
      </geometry>
    </collision>
  </link>
  <joint name="left_arm_mount_plate_joint" type="fixed">
    <parent link="lift_left_mount"/>
    <child link="left_arm_mount_plate"/>
    <origin rpy="0 0 0" xyz="0 0 0"/>
  </joint>
  <!-- Right arm mount plate -->
  <link name="right_arm_mount_plate">
    <visual>
      <geometry>
        <mesh filename="package://dual_arm_mobile_hw/description/meshes/arm_mount.STL"/>
      </geometry>
      <material name="clearpath_dark_grey"/>
    </visual>
    <collision>
      <geometry>
        <mesh filename="package://dual_arm_mobile_hw/description/meshes/arm_mount_collision.STL"/>
      </geometry>
    </collision>
  </link>
  <joint name="right_arm_mount_plate_joint" type="fixed">
    <parent link="lift_right_mount"/>
    <child link="right_arm_mount_plate"/>
    <origin rpy="0 0 3.141592653589793" xyz="0 0 0"/>
  </joint>
  <!-- Dual UR5e mounting links -->
  <link name="left_arm_mount_plate_2"> </link>
  <joint name="left_arm_mount_joint" type="fixed">
    <parent link="left_arm_mount_plate"/>
    <child link="left_arm_mount_plate_2"/>
    <origin rpy="-0.7853981633974483 0 0" xyz="0 0.01628 0.09117"/>
  </joint>
  <link name="right_arm_mount_plate_2"> </link>
  <joint name="right_arm_mount_joint" type="fixed">
    <parent link="right_arm_mount_plate"/>
    <child link="right_arm_mount_plate_2"/>
    <origin rpy="0.7853981633974483 0 3.141592653589793" xyz="0 0.01628 0.09117"/>
  </joint>
  <ros2_control name="clearpath_controller_interface" type="system">
    <hardware>
      <plugin>clearpath_controller_interface/ClearpathControllerInterface</plugin>
      <param name="odom_topic">/r100_0599/platform/odom/offset</param>
      <param name="cmd_vel_topic">/r100_0599/platform/cmd_vel_unstamped</param>
      <param name="max_linear_velocity">0.2</param>
      <param name="max_angular_velocity">0.2</param>
      <param name="cmd_pub_rate">50</param>
    </hardware>
    <joint name="linear_x_joint"/>
    <joint name="linear_y_joint"/>
    <joint name="rotational_yaw_joint"/>
  </ros2_control>
</robot>
