<mujoco model="dual arm robot">
  <compiler angle="radian" meshdir="assets" autolimits="true" />
  <option integrator="implicit" />
  <asset>
    <!-- Clearpath R100 base assets -->
    <mesh name="body" file="body.stl" />
    <mesh name="top" file="top.stl" />
    <mesh name="arm_mount_collision" file="arm_mount_collision.STL" />
    <!-- Ewellix lift assets -->
    <mesh name="lift_plate" file="lifts/plate.obj"/>
    <mesh name="lift_base" file="lifts/base.obj"/>
    <mesh name="lift_lower" file="lifts/lower.obj"/>
    <mesh name="lift_upper" file="lifts/upper.obj"/>
    <mesh name="lift_plate_collision" file="lifts/plate.stl"/>
    <mesh name="lift_base_collision" file="lifts/base.stl"/>
    <mesh name="lift_base_collision2" file="lifts/base2.stl"/>
    <mesh name="lift_lower_collision" file="lifts/lower.stl"/>
    <mesh name="lift_upper_collision" file="lifts/upper.stl"/>
    <!-- UR5E assets -->
    <material class="ur5e" name="black" rgba="0.033 0.033 0.033 1" />
    <material class="ur5e" name="jointgray" rgba="0.278 0.278 0.278 1" />
    <material class="ur5e" name="linkgray" rgba="0.82 0.82 0.82 1" />
    <material class="ur5e" name="urblue" rgba="0.49 0.678 0.8 1" />
    <material name="gray" rgba="0.4627 0.4627 0.4627 1" />
    <material name="metal" rgba="0.58 0.58 0.58 1" />
    <material name="silicone" rgba="0.1882 0.1882 0.1882 1" />
    <material name="white" rgba="1.0 1.0 1.0 1" />
    <mesh file="base_0.obj" />
    <mesh file="base_1.obj" />
    <mesh file="shoulder_0.obj" />
    <mesh file="shoulder_1.obj" />
    <mesh file="shoulder_2.obj" />
    <mesh file="upperarm_0.obj" />
    <mesh file="upperarm_1.obj" />
    <mesh file="upperarm_2.obj" />
    <mesh file="upperarm_3.obj" />
    <mesh file="forearm_0.obj" />
    <mesh file="forearm_1.obj" />
    <mesh file="forearm_2.obj" />
    <mesh file="forearm_3.obj" />
    <mesh file="wrist1_0.obj" />
    <mesh file="wrist1_1.obj" />
    <mesh file="wrist1_2.obj" />
    <mesh file="wrist2_0.obj" />
    <mesh file="wrist2_1.obj" />
    <mesh file="wrist2_2.obj" />
    <mesh file="wrist3.obj" />
    <!-- Robotiq 2f85 meshes -->
    <mesh name="robotiq_85_base" class="2f85" file="robotiq_2f85/base.stl" />
    <mesh name="robotiq_85_knuckle_link" class="2f85" file="robotiq_2f85/knuckle_link.stl" />
    <mesh name="robotiq_85_inner_knuckle_link" class="2f85" file="robotiq_2f85/inner_knuckle_link.stl"/>
    <mesh name="robotiq_85_finger_link" class="2f85" file="robotiq_2f85/finger_link.stl"/>
    <mesh name="robotiq_85_finger_tip_link" class="2f85" file="robotiq_2f85/finger_tip_link.stl"/>
    <mesh name="robotiq_85_pad" class="2f85" file="robotiq_2f85/pad.stl"/>
    <mesh name="robotiq_85_silicone_pad" class="2f85" file="robotiq_2f85/silicone_pad.stl"/>
    <mesh name="camera_adapter" file="camera_adapter.stl" />
  </asset>
  <default>
    <default class="ur5e">
      <material specular="0.5" shininess="0.25" />
      <joint axis="0 1 0" range="-6.28319 6.28319" armature="0.1" />
      <general
        gaintype="fixed"
        biastype="affine"
        ctrlrange="-6.2831 6.2831"
        gainprm="2000"
        biasprm="0 -2000 -400"
        forcerange="-150 150"
      />
      <default class="size3">
        <default class="size3_limited">
          <joint range="-3.1415 3.1415" />
          <general ctrlrange="-3.1415 3.1415" />
        </default>
      </default>
      <default class="size1">
        <general gainprm="500" biasprm="0 -500 -100" forcerange="-28 28" />
      </default>
      <default class="visual">
        <geom type="mesh" contype="0" conaffinity="0" group="2" rgba="0.75294 0.75294 0.75294 1"/>
      </default>
      <default class="mesh_collision">
        <geom type="mesh" group="3"/>
      </default>
      <default class="collision">
        <geom type="capsule" group="3"/>
        <default class="eef_collision">
          <geom type="cylinder" />
        </default>
      </default>
      <site size="0.001" rgba="0.5 0.5 0.5 0.3" group="4" />
    </default>
    <!-- robotiq 2f85 defaults -->
    <default class="2f85">
      <mesh scale="0.001 0.001 0.001" />
      <general biastype="affine" />
      <joint axis="1 0 0" />
      <default class="knuckle_link">
        <joint
          range="0 0.8"
          armature="0.005"
          damping="0.1"
          solimplimit="0.95 0.99 0.001"
          solreflimit="0.005 1"
        />
      </default>
      <default class="finger_tip_link">
        <joint
          range="-0.872664 0.872664"
          armature="0.001"
          pos="0 -0.018 0.0065"
          solimplimit="0.95 0.99 0.001"
          solreflimit="0.005 1"
        />
      </default>
      <default class="inner_knuckle_link">
        <joint
          range="-0.29670597283 0.8"
          armature="0.001"
          stiffness="0.05"
          springref="2.62"
          damping="0.00125"
        />
      </default>
      <default class="finger_link">
        <joint
          range="-1.57 0"
          armature="0.001"
          solimplimit="0.95 0.99 0.001"
          solreflimit="0.005 1"
        />
      </default>
      <default class="2f85_visual">
        <geom type="mesh" contype="0" conaffinity="0" group="2" />
      </default>
      <default class="2f85_collision">
        <geom type="mesh" group="3" condim="6" />
        <default class="pad_box1">
          <geom
            mass="0"
            type="box"
            pos="0 -0.0026 0.028125"
            size="0.011 0.004 0.009375"
            friction="0.7"
            solimp="0.95 0.99 0.001"
            solref="0.004 1"
            priority="1"
            rgba="0.55 0.55 0.55 1"
          />
        </default>
        <default class="pad_box2">
          <geom
            mass="0"
            type="box"
            pos="0 -0.0026 0.009375"
            size="0.011 0.004 0.009375"
            friction="0.6"
            solimp="0.95 0.99 0.001"
            solref="0.004 1"
            priority="1"
            rgba="0.45 0.45 0.45 1"
          />
        </default>
      </default>
    </default>
  </default>
  <worldbody>
    <body name="base_platform_rotation" pos="0 0 0" quat="1 0 0 0">
      <inertial mass="0.01" pos="0 0 0" diaginertia="0.001 0.001 0.001"/>
      <joint name="linear_x_joint" type="slide" axis="1 0 0"/>
      <joint name="linear_y_joint" type="slide" axis="0 1 0"/>
      <joint name="rotational_yaw_joint" type="hinge" axis="0 0 1"/>
      <body name="base_link">
        <geom type="mesh" class="visual" rgba="0.15 0.15 0.15 1" mesh="body"/>
        <geom size="0.2465 0.2465 0.0275" pos="0 0 0.2475" quat="0.92388 0 0 0.382683" type="box" rgba="0.4 0.4 0.4 1"/>
        <geom type="mesh" rgba="0.15 0.15 0.15 1" mesh="top"/>
        <!-- Back body component box -->
        <geom size="0.1895 0.395 0.113" pos="-0.289 0 0.393" type="box" rgba="0.15 0.15 0.15 1"/>
        <!-- Front body component box -->
        <geom size="0.1895 0.395 0.113" pos="0.289 0 0.393" quat="0 0 0 1" type="box" rgba="0.15 0.15 0.15 1"/>
        <!-- Screen bar 1 -->
        <geom size="0.02 0.225 0.018" pos="-0.4 0 0.52335" type="box" rgba="0.15 0.15 0.15 1"/>
        <!-- Screen bar 2 -->
        <geom size="0.0275 0.225 0.02" pos="-0.4096 0 0.535116" quat="0.932327 0 0.361615 0" type="box" rgba="0.15 0.15 0.15 1"/>
        <!-- Left screen -->
        <geom size="0.0355 0.13 0.088" pos="-0.439267 0.18 0.564913" quat="0.932327 0 0.361615 0" type="box" rgba="0.15 0.15 0.15 1"/>
        <!-- Right screen -->
        <geom size="0.0355 0.13 0.088" pos="-0.439267 -0.18 0.564913" quat="0.932327 0 0.361615 0" type="box" rgba="0.15 0.15 0.15 1"/>
        <!-- Antennas -->
        <geom size="0.033 0.1145" pos="-0.089 -0.384 0.589" type="cylinder" rgba="0.15 0.15 0.15 1"/>
        <geom size="0.033 0.1145" pos="-0.089 0.384 0.589" type="cylinder" rgba="0.15 0.15 0.15 1"/>
        <geom size="0.037 0.0735" pos="0.0865 -0.384 0.549" type="cylinder" rgba="0.15 0.15 0.15 1"/>
        <!-- Wheels -->
        <body name="front_rocker_link" pos="0.319 0 0.05">
          <inertial
              pos="0 0 0"
              quat="0.475329 0.523511 0.47531 0.523526"
              mass="10.267"
              diaginertia="0.432583 0.412817 0.0288"
          />
          <!-- This joint needs to be disabled for an unknown reason -->
          <joint
              name="front_rocker"
              pos="0 0 0"
              axis="1 0 0"
              range="-0.08726 0.08726"
          />
          <body name="front_left_wheel_link" pos="0 0.2755 0.07">
            <include file="front_left_wheel_link.xml" />
          </body>
          <body name="front_right_wheel_link" pos="0 -0.2755 0.07">
            <include file="front_right_wheel_link.xml" />
          </body>
        </body>
        <body name="rear_left_wheel_link" pos="-0.319 0.2755 0.12">
          <include file="rear_left_wheel_link.xml" />
        </body>
        <body name="rear_right_wheel_link" pos="-0.319 -0.2755 0.12">
          <include file="rear_right_wheel_link.xml" />
        </body>
        <!-- Left chain -->
        <body name="lift_left_plate_link" pos="0 0.2 0.3274" gravcomp="1">
          <geom class="visual" mesh="lift_plate"/>
          <geom class="mesh_collision" mesh="lift_plate_collision"/>
          <body name="lift_left_base_link" pos="0 0.0 0.015" gravcomp="1">
            <geom class="visual" pos="0.0 0.0 -0.0151" mesh="lift_base"/>
            <geom class="mesh_collision" pos="0.0 0.0 -0.0151" mesh="lift_base_collision"/>
            <geom class="mesh_collision" pos="0.0 0.0 -0.0151" mesh="lift_base_collision2"/>
            <body name="lift_left_lower_link" pos="0 0.0 0.0" gravcomp="1">
              <inertial pos="0 0 0.2415" mass="10" diaginertia="0.21276 0.21276 0.0367043"/>
              <joint name="lift_left_lower_joint" pos="0 0 0" axis="0 0 1" type="slide" range="0 0.25" />
              <geom class="visual" pos="0 0 -0.2721" mesh="lift_lower"/>
              <geom class="mesh_collision" pos="0.0 0.0 -0.2721" mesh="lift_lower_collision"/>
              <body name="lift_left_upper_link" pos="0 0.0 0.025" gravcomp="1">
                <inertial pos="0 0 0.245" mass="10" diaginertia="0.213951 0.213951 0.027735"/>
                <joint name="lift_left_upper_joint" pos="0 0 0" axis="0 0 1" type="slide" range="0 0.25"/>
                <geom class="visual" pos="0 0 -0.5151" mesh="lift_upper"/>
                <geom class="mesh_collision" pos="0.0 0.0 -0.5151" mesh="lift_upper_collision"/>
                <body name="left_arm_mount" pos="0.0 0.0 0.49" gravcomp="1">
                  <geom type="mesh" rgba="0.15 0.15 0.15 1" mesh="arm_mount_collision"/>
                  <!-- Left UR5E -->
                  <body name="left_base" gravcomp="1" pos="0 0.01628 0.09117" quat="-0.853554 0.354 0.146 0.354" childclass="ur5e">
                    <inertial mass="4.0" pos="0 0 0" diaginertia="0.00443333156 0.00443333156 0.0072"/>
                    <geom mesh="base_0" material="black" class="visual" />
                    <geom mesh="base_1" material="jointgray" class="visual" />
                    <body name="left_shoulder_link" gravcomp="1" pos="0 0 0.163">
                      <inertial mass="3.7" pos="0 0 0" diaginertia="0.0102675 0.0102675 0.00666"/>
                      <joint name="left_shoulder_pan_joint" class="size3" axis="0 0 1"/>
                      <geom mesh="shoulder_0" material="urblue" class="visual" />
                      <geom mesh="shoulder_1" material="black" class="visual" />
                      <geom mesh="shoulder_2" material="jointgray" class="visual" />
                      <geom class="collision" size="0.06 0.06" pos="0 0 -0.04" />
                      <body name="left_upper_arm_link" gravcomp="1" pos="0 0.138 0" quat="1 0 1 0">
                        <inertial mass="8.393" pos="0 0 0.2125" diaginertia="0.133886 0.133886 0.0151074"/>
                        <joint name="left_shoulder_lift_joint" class="size3" />
                        <geom mesh="upperarm_0" material="linkgray" class="visual" />
                        <geom mesh="upperarm_1" material="black" class="visual" />
                        <geom mesh="upperarm_2" material="jointgray" class="visual" />
                        <geom mesh="upperarm_3" material="urblue" class="visual" />
                        <geom class="collision" pos="0 -0.04 0" quat="1 1 0 0" size="0.06 0.06"/>
                        <geom class="collision" size="0.05 0.2" pos="0 0 0.2" />
                        <body name="left_forearm_link" gravcomp="1" pos="0 -0.131 0.425">
                          <inertial mass="2.275" pos="0 0 0.196" diaginertia="0.0311796 0.0311796 0.004095"/>
                          <joint name="left_elbow_joint" class="size3_limited" />
                          <geom mesh="forearm_0" material="urblue" class="visual" />
                          <geom mesh="forearm_1" material="linkgray" class="visual" />
                          <geom mesh="forearm_2" material="black" class="visual" />
                          <geom mesh="forearm_3" material="jointgray" class="visual" />
                          <geom class="collision" pos="0 0.08 0" quat="1 1 0 0" size="0.055 0.06"/>
                          <geom class="collision" size="0.038 0.19" pos="0 0 0.2" />
                          <body name="left_wrist_1_link" gravcomp="1" pos="0 0 0.392" quat="1 0 1 0">
                            <inertial mass="1.219" pos="0 0.127 0" diaginertia="0.0025599 0.0025599 0.0021942"/>
                            <joint name="left_wrist_1_joint" class="size1" />
                            <geom mesh="wrist1_0" material="black" class="visual" />
                            <geom mesh="wrist1_1" material="urblue" class="visual" />
                            <geom mesh="wrist1_2" material="jointgray" class="visual" />
                            <geom class="collision" pos="0 0.05 0" quat="1 1 0 0" size="0.04 0.07"/>
                            <body name="left_wrist_2_link" gravcomp="1" pos="0 0.127 0">
                              <inertial mass="1.219" pos="0 0 0.1" diaginertia="0.0025599 0.0025599 0.0021942"/>
                              <joint name="left_wrist_2_joint" axis="0 0 1" class="size1"/>
                              <geom mesh="wrist2_0" material="black" class="visual"/>
                              <geom mesh="wrist2_1" material="urblue" class="visual"/>
                              <geom mesh="wrist2_2" material="jointgray" class="visual"/>
                              <geom class="collision" size="0.04 0.06" pos="0 0 0.04"/>
                              <geom class="collision" pos="0 0.02 0.1" quat="1 1 0 0" size="0.04 0.04"/>
                              <body name="left_wrist_3_link" gravcomp="1" pos="0 0 0.1">
                                <inertial mass="0.1889" pos="0 0.0771683 0" quat="1 0 0 1"
                                          diaginertia="0.000132134 9.90863e-05 9.90863e-05"/>
                                <joint name="left_wrist_3_joint" class="size1"/>
                                <geom material="linkgray" mesh="wrist3" class="visual"/>
                                <geom class="eef_collision" pos="0 0.08 0" quat="1 1 0 0" size="0.04 0.02"/>
                                <site name="left_attachment_site" pos="0 0.1 0" quat="-1 1 0 0"/>
                                <!-- Left Robotiq + end effector attachments -->
                                <body>
                                  <!-- site for end effector's f/t sensor right at the base of the robotiq gripper -->
                                  <site name="left_robotiq_ft_sensor" size="0.01" pos="0 0.1 0" quat="-1 1 0 0"/>
                                  <body name="left_camera_adapter" gravcomp="1" pos="0.0 0.1 0" euler="-1.57 3.14 0">
                                    <geom mesh="camera_adapter" material="linkgray" class="visual"/>
                                  </body>
                                  <camera name="left_wrist_camera" pos="0.0 0.2 0.1" fovy="58" mode="fixed" resolution="1280 720" euler="1.57 0.0 0.0"/>
                                  <site name="left_wrist_camera_optical_frame" pos="0.0 0.2 0.1" euler="-1.57 0 0"/>
                                  <body childclass="2f85">
                                    <body name="left_robotiq_85_base_link" gravcomp="1" pos="0.0 0.1 0" quat="0.5 -0.5 0.5 0.5">
                                      <inertial mass="0.777441" pos="0 -2.70394e-05 0.0354675" quat="1 -0.00152849 0 0" diaginertia="0.000260285 0.000225381 0.000152708"/>
                                      <geom class="visual" mesh="robotiq_85_base" material="black"/>
                                      <geom class="collision" mesh="robotiq_85_base"/>
                                      <site name="left_pinch" pos="0 0 0.145" type="sphere" group="5" rgba="0.9 0.9 0.9 1" size="0.005"/>
                                      <body name="left_robotiq_85_right_knuckle_link" gravcomp="1" pos="0 0.0306011 0.054904">
                                        <inertial mass="0.00899563" pos="2.96931e-12 0.0177547 0.00107314" quat="0.681301 0.732003 0 0" diaginertia="1.72352e-06 1.60906e-06 3.22006e-07"/>
                                        <joint name="left_robotiq_85_right_knuckle_joint" class="knuckle_link"/>
                                        <geom class="visual" mesh="robotiq_85_knuckle_link" material="gray"/>
                                        <geom class="collision" mesh="robotiq_85_knuckle_link"/>
                                        <body name="left_robotiq_85_right_finger_link" gravcomp="1" pos="0 0.0315 -0.0041">
                                          <inertial mass="0.0140974" pos="0 0.00301209 0.0232175" quat="0.705636 -0.0455904 0.0455904 0.705636" diaginertia="4.16206e-06 3.52216e-06 8.88131e-07"/>
                                          <joint name="left_robotiq_85_right_finger_joint" class="finger_link"/>
                                          <geom class="visual" mesh="robotiq_85_finger_link" material="black"/>
                                          <geom class="collision" mesh="robotiq_85_finger_link"/>
                                        </body>
                                      </body>
                                      <body name="left_robotiq_85_right_inner_knuckle_link" gravcomp="1" pos="0 0.0132 0.0609">
                                        <inertial mass="0.0221642" pos="-8.65005e-09 0.0181624 0.0212658" quat="0.663403 -0.244737 0.244737 0.663403" diaginertia="8.96853e-06 6.71733e-06 2.63931e-06"/>
                                        <joint name="left_robotiq_85_right_inner_knuckle_joint" class="inner_knuckle_link"/>
                                        <geom class="visual" mesh="robotiq_85_inner_knuckle_link" material="black"/>
                                        <geom class="collision" mesh="robotiq_85_inner_knuckle_link"/>
                                        <body name="left_robotiq_85_right_finger_tip_link" gravcomp="1" pos="0 0.055 0.0375">
                                          <inertial mass="0.0125222" pos="0 -0.011046 0.0124786" quat="1 0.1664 0 0" diaginertia="2.67415e-06 2.4559e-06 6.02031e-07"/>
                                          <joint name="left_robotiq_85_right_finger_tip_joint" class="finger_tip_link"/>
                                          <geom class="visual" mesh="robotiq_85_finger_tip_link" material="black"/>
                                          <geom class="collision" mesh="robotiq_85_finger_tip_link"/>
                                          <body name="left_right_pad" gravcomp="1" pos="0 -0.0189 0.01352">
                                            <geom class="pad_box1" name="left_right_pad1"/>
                                            <geom class="pad_box2" name="left_right_pad2"/>
                                            <inertial mass="0.0035" pos="0 -0.0025 0.0185" quat="0.707107 0 0 0.707107" diaginertia="4.73958e-07 3.64583e-07 1.23958e-07"/>
                                            <geom class="visual" mesh="robotiq_85_pad"/>
                                            <body name="left_right_silicone_pad" gravcomp="1">
                                              <geom class="visual" mesh="robotiq_85_silicone_pad" material="black"/>
                                            </body>
                                          </body>
                                        </body>
                                      </body>
                                      <body name="left_robotiq_85_left_knuckle_link" gravcomp="1" pos="0 -0.0306011 0.054904" quat="0 0 0 1">
                                        <inertial mass="0.00899563" pos="0 0.0177547 0.00107314" quat="0.681301 0.732003 0 0" diaginertia="1.72352e-06 1.60906e-06 3.22006e-07"/>
                                        <joint name="left_robotiq_85_left_knuckle_joint" class="knuckle_link"/>
                                        <geom class="visual" mesh="robotiq_85_knuckle_link" material="gray"/>
                                        <geom class="collision" mesh="robotiq_85_knuckle_link"/>
                                        <body name="left_robotiq_85_left_finger_link" gravcomp="1" pos="0 0.0315 -0.0041">
                                          <inertial mass="0.0140974" pos="0 0.00301209 0.0232175" quat="0.705636 -0.0455904 0.0455904 0.705636" diaginertia="4.16206e-06 3.52216e-06 8.88131e-07"/>
                                          <joint name="left_robotiq_85_left_finger_joint" class="finger_link"/>
                                          <geom class="visual" mesh="robotiq_85_finger_link" material="black"/>
                                          <geom class="collision" mesh="robotiq_85_finger_link"/>
                                        </body>
                                      </body>
                                      <body name="left_robotiq_85_left_inner_knuckle_link" gravcomp="1" pos="0 -0.0132 0.0609" quat="0 0 0 1">
                                        <inertial mass="0.0221642" pos="-8.65005e-09 0.0181624 0.0212658" quat="0.663403 -0.244737 0.244737 0.663403" diaginertia="8.96853e-06 6.71733e-06 2.63931e-06"/>
                                        <joint name="left_robotiq_85_left_inner_knuckle_joint" class="inner_knuckle_link"/>
                                        <geom class="visual" mesh="robotiq_85_inner_knuckle_link" material="black"/>
                                        <geom class="collision" mesh="robotiq_85_inner_knuckle_link"/>
                                        <body name="left_robotiq_85_left_finger_tip_link" gravcomp="1" pos="0 0.055 0.0375">
                                          <inertial mass="0.0125222" pos="0 -0.011046 0.0124786" quat="1 0.1664 0 0" diaginertia="2.67415e-06 2.4559e-06 6.02031e-07"/>
                                          <joint name="left_robotiq_85_left_finger_tip_joint" class="finger_tip_link"/>
                                          <geom class="visual" mesh="robotiq_85_finger_tip_link" material="black"/>
                                          <geom class="collision" mesh="robotiq_85_finger_tip_link"/>
                                          <body name="left_left_pad" gravcomp="1" pos="0 -0.0189 0.01352">
                                            <geom class="pad_box1" name="left_left_pad1"/>
                                            <geom class="pad_box2" name="left_left_pad2"/>
                                            <inertial mass="0.0035" pos="0 -0.0025 0.0185" quat="1 0 0 1" diaginertia="4.73958e-07 3.64583e-07 1.23958e-07"/>
                                            <geom class="visual" mesh="robotiq_85_pad"/>
                                            <body name="left_left_silicone_pad" gravcomp="1">
                                              <geom class="visual" mesh="robotiq_85_silicone_pad" material="black"/>
                                            </body>
                                          </body>
                                        </body>
                                      </body>
                                    </body>
                                  </body>
                                </body>
                              </body>
                            </body>
                          </body>
                        </body>
                      </body>
                    </body>
                  </body>
                </body>
              </body>
            </body>
          </body>
        </body>
        <!-- Right chain -->
        <body name="lift_right_plate_link" pos="0 -0.2 0.3274" gravcomp="1">
          <geom class="visual" mesh="lift_plate"/>
          <geom class="mesh_collision" mesh="lift_plate_collision"/>
          <body name="lift_right_base_link" pos="0 0.0 0.015" gravcomp="1">
            <geom class="visual" pos="0.0 0.0 -0.0151" mesh="lift_base"/>
            <geom class="mesh_collision" pos="0.0 0.0 -0.0151" mesh="lift_base_collision"/>
            <geom class="mesh_collision" pos="0.0 0.0 -0.0151" mesh="lift_base_collision2"/>
            <body name="lift_right_lower_link" pos="0 0.0 0.0" gravcomp="1">
              <inertial pos="0 0 0.2415" mass="10" diaginertia="0.21276 0.21276 0.0367043"/>
              <joint name="lift_right_lower_joint" pos="0 0 0" axis="0 0 1" type="slide" range="0 0.25" />
              <geom class="visual" pos="0 0 -0.2721" mesh="lift_lower"/>
              <geom class="mesh_collision" pos="0.0 0.0 -0.2721" mesh="lift_lower_collision"/>
              <body name="lift_right_upper_link" pos="0 0.0 0.025" gravcomp="1">
                <inertial pos="0 0 0.245" mass="10" diaginertia="0.213951 0.213951 0.027735"/>
                <joint name="lift_right_upper_joint" pos="0 0 0" axis="0 0 1" type="slide" range="0 0.25"/>
                <geom class="visual" pos="0 0 -0.5151" mesh="lift_upper"/>
                <geom class="mesh_collision" pos="0.0 0.0 -0.5151" mesh="lift_upper_collision"/>
                <body name="right_arm_mount" pos="0.0 0.0 0.49" quat="0.0 0.0 0.0 1.0" gravcomp="1">
                  <geom type="mesh" rgba="0.15 0.15 0.15 1" mesh="arm_mount_collision"/>
                  <!-- Right UR5E -->
                  <body name="right_base" gravcomp="1" pos="0 0.01628 0.09117" quat="-0.853554 0.354 -0.146 -0.354" childclass="ur5e">
                    <inertial mass="4.0" pos="0 0 0" diaginertia="0.00443333156 0.00443333156 0.0072"/>
                    <geom mesh="base_0" material="black" class="visual" />
                    <geom mesh="base_1" material="jointgray" class="visual" />
                    <body name="right_shoulder_link" gravcomp="1" pos="0 0 0.163">
                      <inertial mass="3.7" pos="0 0 0" diaginertia="0.0102675 0.0102675 0.00666"/>
                      <joint name="right_shoulder_pan_joint" class="size3" axis="0 0 1"/>
                      <geom mesh="shoulder_0" material="urblue" class="visual" />
                      <geom mesh="shoulder_1" material="black" class="visual" />
                      <geom mesh="shoulder_2" material="jointgray" class="visual" />
                      <geom class="collision" size="0.06 0.06" pos="0 0 -0.04" />
                      <body name="right_upper_arm_link" gravcomp="1" pos="0 0.138 0" quat="1 0 1 0">
                        <inertial mass="8.393" pos="0 0 0.2125" diaginertia="0.133886 0.133886 0.0151074"/>
                        <joint name="right_shoulder_lift_joint" class="size3" />
                        <geom mesh="upperarm_0" material="linkgray" class="visual" />
                        <geom mesh="upperarm_1" material="black" class="visual" />
                        <geom mesh="upperarm_2" material="jointgray" class="visual" />
                        <geom mesh="upperarm_3" material="urblue" class="visual" />
                        <geom class="collision" pos="0 -0.04 0" quat="1 1 0 0" size="0.06 0.06"/>
                        <geom class="collision" size="0.05 0.2" pos="0 0 0.2" />
                        <body name="right_forearm_link" gravcomp="1" pos="0 -0.131 0.425">
                          <inertial mass="2.275" pos="0 0 0.196" diaginertia="0.0311796 0.0311796 0.004095"/>
                          <joint name="right_elbow_joint" class="size3_limited" />
                          <geom mesh="forearm_0" material="urblue" class="visual" />
                          <geom mesh="forearm_1" material="linkgray" class="visual" />
                          <geom mesh="forearm_2" material="black" class="visual" />
                          <geom mesh="forearm_3" material="jointgray" class="visual" />
                          <geom class="collision" pos="0 0.08 0" quat="1 1 0 0" size="0.055 0.06"/>
                          <geom class="collision" size="0.038 0.19" pos="0 0 0.2" />
                          <body name="right_wrist_1_link" gravcomp="1" pos="0 0 0.392" quat="1 0 1 0">
                            <inertial mass="1.219" pos="0 0.127 0" diaginertia="0.0025599 0.0025599 0.0021942"/>
                            <joint name="right_wrist_1_joint" class="size1" />
                            <geom mesh="wrist1_0" material="black" class="visual" />
                            <geom mesh="wrist1_1" material="urblue" class="visual" />
                            <geom mesh="wrist1_2" material="jointgray" class="visual" />
                            <geom class="collision" pos="0 0.05 0" quat="1 1 0 0" size="0.04 0.07"/>
                            <body name="right_wrist_2_link" gravcomp="1" pos="0 0.127 0">
                              <inertial mass="1.219" pos="0 0 0.1" diaginertia="0.0025599 0.0025599 0.0021942"/>
                              <joint name="right_wrist_2_joint" axis="0 0 1" class="size1"/>
                              <geom mesh="wrist2_0" material="black" class="visual"/>
                              <geom mesh="wrist2_1" material="urblue" class="visual"/>
                              <geom mesh="wrist2_2" material="jointgray" class="visual"/>
                              <geom class="collision" size="0.04 0.06" pos="0 0 0.04"/>
                              <geom class="collision" pos="0 0.02 0.1" quat="1 1 0 0" size="0.04 0.04"/>
                              <body name="right_wrist_3_link" gravcomp="1" pos="0 0 0.1">
                                <inertial mass="0.1889" pos="0 0.0771683 0" quat="1 0 0 1"
                                          diaginertia="0.000132134 9.90863e-05 9.90863e-05"/>
                                <joint name="right_wrist_3_joint" class="size1"/>
                                <geom material="linkgray" mesh="wrist3" class="visual"/>
                                <geom class="eef_collision" pos="0 0.08 0" quat="1 1 0 0" size="0.04 0.02"/>
                                <site name="right_attachment_site" pos="0 0.1 0" quat="-1 1 0 0"/>
                                <!-- Left Robotiq + end effector attachments -->
                                <body>
                                  <!-- site for end effector's f/t sensor right at the base of the robotiq gripper -->
                                  <site name="right_robotiq_ft_sensor" size="0.01" pos="0 0.1 0" quat="-1 1 0 0"/>
                                  <body name="right_camera_adapter" gravcomp="1" pos="0.0 0.1 0" euler="-1.57 3.14 0">
                                    <geom mesh="camera_adapter" material="linkgray" class="visual"/>
                                  </body>
                                  <camera name="right_wrist_camera" pos="0.0 0.2 0.1" fovy="58" mode="fixed" resolution="1280 720" euler="1.57 0.0 0.0"/>
                                  <site name="right_wrist_camera_optical_frame" pos="0.0 0.2 0.1" euler="-1.57 0 0"/>
                                  <body childclass="2f85">
                                    <body name="right_robotiq_85_base_link" gravcomp="1" pos="0.0 0.1 0" quat="0.5 -0.5 0.5 0.5">
                                      <inertial mass="0.777441" pos="0 -2.70394e-05 0.0354675" quat="1 -0.00152849 0 0" diaginertia="0.000260285 0.000225381 0.000152708"/>
                                      <geom class="visual" mesh="robotiq_85_base" material="black"/>
                                      <geom class="collision" mesh="robotiq_85_base"/>
                                      <site name="right_pinch" pos="0 0 0.145" type="sphere" group="5" rgba="0.9 0.9 0.9 1" size="0.005"/>
                                      <body name="right_robotiq_85_right_knuckle_link" gravcomp="1" pos="0 0.0306011 0.054904">
                                        <inertial mass="0.00899563" pos="2.96931e-12 0.0177547 0.00107314" quat="0.681301 0.732003 0 0" diaginertia="1.72352e-06 1.60906e-06 3.22006e-07"/>
                                        <joint name="right_robotiq_85_right_knuckle_joint" class="knuckle_link"/>
                                        <geom class="visual" mesh="robotiq_85_knuckle_link" material="gray"/>
                                        <geom class="collision" mesh="robotiq_85_knuckle_link"/>
                                        <body name="right_robotiq_85_right_finger_link" gravcomp="1" pos="0 0.0315 -0.0041">
                                          <inertial mass="0.0140974" pos="0 0.00301209 0.0232175" quat="0.705636 -0.0455904 0.0455904 0.705636" diaginertia="4.16206e-06 3.52216e-06 8.88131e-07"/>
                                          <joint name="right_robotiq_85_right_finger_joint" class="finger_link"/>
                                          <geom class="visual" mesh="robotiq_85_finger_link" material="black"/>
                                          <geom class="collision" mesh="robotiq_85_finger_link"/>
                                        </body>
                                      </body>
                                      <body name="right_robotiq_85_right_inner_knuckle_link" gravcomp="1" pos="0 0.0132 0.0609">
                                        <inertial mass="0.0221642" pos="-8.65005e-09 0.0181624 0.0212658" quat="0.663403 -0.244737 0.244737 0.663403" diaginertia="8.96853e-06 6.71733e-06 2.63931e-06"/>
                                        <joint name="right_robotiq_85_right_inner_knuckle_joint" class="inner_knuckle_link"/>
                                        <geom class="visual" mesh="robotiq_85_inner_knuckle_link" material="black"/>
                                        <geom class="collision" mesh="robotiq_85_inner_knuckle_link"/>
                                        <body name="right_robotiq_85_right_finger_tip_link" gravcomp="1" pos="0 0.055 0.0375">
                                          <inertial mass="0.0125222" pos="0 -0.011046 0.0124786" quat="1 0.1664 0 0" diaginertia="2.67415e-06 2.4559e-06 6.02031e-07"/>
                                          <joint name="right_robotiq_85_right_finger_tip_joint" class="finger_tip_link"/>
                                          <geom class="visual" mesh="robotiq_85_finger_tip_link" material="black"/>
                                          <geom class="collision" mesh="robotiq_85_finger_tip_link"/>
                                          <body name="right_right_pad" gravcomp="1" pos="0 -0.0189 0.01352">
                                            <geom class="pad_box1" name="right_right_pad1"/>
                                            <geom class="pad_box2" name="right_right_pad2"/>
                                            <inertial mass="0.0035" pos="0 -0.0025 0.0185" quat="0.707107 0 0 0.707107" diaginertia="4.73958e-07 3.64583e-07 1.23958e-07"/>
                                            <geom class="visual" mesh="robotiq_85_pad"/>
                                            <body name="right_right_silicone_pad" gravcomp="1">
                                              <geom class="visual" mesh="robotiq_85_silicone_pad" material="black"/>
                                            </body>
                                          </body>
                                        </body>
                                      </body>
                                      <body name="right_robotiq_85_left_knuckle_link" gravcomp="1" pos="0 -0.0306011 0.054904" quat="0 0 0 1">
                                        <inertial mass="0.00899563" pos="0 0.0177547 0.00107314" quat="0.681301 0.732003 0 0" diaginertia="1.72352e-06 1.60906e-06 3.22006e-07"/>
                                        <joint name="right_robotiq_85_left_knuckle_joint" class="knuckle_link"/>
                                        <geom class="visual" mesh="robotiq_85_knuckle_link" material="gray"/>
                                        <geom class="collision" mesh="robotiq_85_knuckle_link"/>
                                        <body name="right_robotiq_85_left_finger_link" gravcomp="1" pos="0 0.0315 -0.0041">
                                          <inertial mass="0.0140974" pos="0 0.00301209 0.0232175" quat="0.705636 -0.0455904 0.0455904 0.705636" diaginertia="4.16206e-06 3.52216e-06 8.88131e-07"/>
                                          <joint name="right_robotiq_85_left_finger_joint" class="finger_link"/>
                                          <geom class="visual" mesh="robotiq_85_finger_link" material="black"/>
                                          <geom class="collision" mesh="robotiq_85_finger_link"/>
                                        </body>
                                      </body>
                                      <body name="right_robotiq_85_left_inner_knuckle_link" gravcomp="1" pos="0 -0.0132 0.0609" quat="0 0 0 1">
                                        <inertial mass="0.0221642" pos="-8.65005e-09 0.0181624 0.0212658" quat="0.663403 -0.244737 0.244737 0.663403" diaginertia="8.96853e-06 6.71733e-06 2.63931e-06"/>
                                        <joint name="right_robotiq_85_left_inner_knuckle_joint" class="inner_knuckle_link"/>
                                        <geom class="visual" mesh="robotiq_85_inner_knuckle_link" material="black"/>
                                        <geom class="collision" mesh="robotiq_85_inner_knuckle_link"/>
                                        <body name="right_robotiq_85_left_finger_tip_link" gravcomp="1" pos="0 0.055 0.0375">
                                          <inertial mass="0.0125222" pos="0 -0.011046 0.0124786" quat="1 0.1664 0 0" diaginertia="2.67415e-06 2.4559e-06 6.02031e-07"/>
                                          <joint name="right_robotiq_85_left_finger_tip_joint" class="finger_tip_link"/>
                                          <geom class="visual" mesh="robotiq_85_finger_tip_link" material="black"/>
                                          <geom class="collision" mesh="robotiq_85_finger_tip_link"/>
                                          <body name="right_left_pad" gravcomp="1" pos="0 -0.0189 0.01352">
                                            <geom class="pad_box1" name="right_left_pad1"/>
                                            <geom class="pad_box2" name="right_left_pad2"/>
                                            <inertial mass="0.0035" pos="0 -0.0025 0.0185" quat="1 0 0 1" diaginertia="4.73958e-07 3.64583e-07 1.23958e-07"/>
                                            <geom class="visual" mesh="robotiq_85_pad"/>
                                            <body name="right_left_silicone_pad" gravcomp="1">
                                              <geom class="visual" mesh="robotiq_85_silicone_pad" material="black"/>
                                            </body>
                                          </body>
                                        </body>
                                      </body>
                                    </body>
                                  </body>
                                </body>
                              </body>
                            </body>
                          </body>
                        </body>
                      </body>
                    </body>
                  </body>
                </body>
              </body>
            </body>
          </body>
        </body>
      </body>
    </body>
  </worldbody>

  <contact>
    <!-- Lift contact excludes -->
    <exclude body1="lift_left_plate_link" body2="lift_left_lower_link"/>
    <exclude body1="lift_left_base_link" body2="lift_left_upper_link"/>
    <exclude body1="lift_left_base_link" body2="lift_left_lower_link"/>
    <exclude body1="lift_right_plate_link" body2="lift_right_lower_link"/>
    <exclude body1="lift_right_base_link" body2="lift_right_upper_link"/>
    <exclude body1="lift_right_base_link" body2="lift_right_lower_link"/>
    <!-- Left gripper contact excludes -->
    <exclude body1="left_robotiq_85_base_link" body2="left_robotiq_85_left_knuckle_link"/>
    <exclude body1="left_robotiq_85_base_link" body2="left_robotiq_85_right_knuckle_link"/>
    <exclude body1="left_robotiq_85_base_link" body2="left_robotiq_85_left_inner_knuckle_link"/>
    <exclude body1="left_robotiq_85_base_link" body2="left_robotiq_85_right_inner_knuckle_link"/>
    <exclude body1="left_robotiq_85_right_finger_link" body2="left_robotiq_85_right_finger_tip_link"/>
    <exclude body1="left_robotiq_85_left_finger_link" body2="left_robotiq_85_left_finger_tip_link"/>
  </contact>

  <tendon>
    <!-- Robotiq tendons -->
    <fixed name="left_split">
      <joint joint="left_robotiq_85_right_knuckle_joint" coef="0.5"/>
      <joint joint="left_robotiq_85_left_knuckle_joint" coef="0.5"/>
    </fixed>
    <fixed name="right_split">
      <joint joint="right_robotiq_85_right_knuckle_joint" coef="0.5"/>
      <joint joint="right_robotiq_85_left_knuckle_joint" coef="0.5"/>
    </fixed>
  </tendon>

  <equality>
    <!-- Lift equalities -->
    <joint joint1="lift_left_lower_joint" joint2="lift_left_upper_joint" polycoef="0 1.0 0 0 0"/>
    <joint joint1="lift_right_lower_joint" joint2="lift_right_upper_joint" polycoef="0 1.0 0 0 0"/>
    <!-- Gripper equalities -->
    <connect anchor="0 0 0" body1="left_robotiq_85_right_finger_tip_link" body2="left_robotiq_85_right_finger_link"
             solimp="0.95 0.99 0.001" solref="0.005 1"/>
    <connect anchor="0 0 0" body1="left_robotiq_85_left_finger_tip_link" body2="left_robotiq_85_left_finger_link"
             solimp="0.95 0.99 0.001" solref="0.005 1"/>
    <joint joint1="left_robotiq_85_left_knuckle_joint" joint2="left_robotiq_85_right_knuckle_joint" polycoef="0 1 0 0 0"
           solimp="0.95 0.99 0.001" solref="0.005 1"/>
    <connect anchor="0 0 0" body1="right_robotiq_85_right_finger_tip_link" body2="right_robotiq_85_right_finger_link"
             solimp="0.95 0.99 0.001" solref="0.005 1"/>
    <connect anchor="0 0 0" body1="right_robotiq_85_left_finger_tip_link" body2="right_robotiq_85_left_finger_link"
             solimp="0.95 0.99 0.001" solref="0.005 1"/>
    <joint joint1="right_robotiq_85_left_knuckle_joint" joint2="right_robotiq_85_right_knuckle_joint" polycoef="0 1 0 0 0"
           solimp="0.95 0.99 0.001" solref="0.005 1"/>
  </equality>

  <sensor>
    <force site="left_robotiq_ft_sensor" />
    <torque site="left_robotiq_ft_sensor" />
    <force site="right_robotiq_ft_sensor" />
    <torque site="right_robotiq_ft_sensor" />
  </sensor>

  <actuator>
    <!-- Wheel actuators -->
    <velocity name="front_right_wheel_joint" joint="front_right_wheel_joint" ctrlrange="-15 15" kv="50"/>
    <velocity name="front_left_wheel_joint" joint="front_left_wheel_joint" ctrlrange="-15 15" kv="50"/>
    <velocity name="rear_right_wheel_joint" joint="rear_right_wheel_joint" ctrlrange="-15 15" kv="50"/>
    <velocity name="rear_left_wheel_joint" joint="rear_left_wheel_joint" ctrlrange="-15 15" kv="50"/>
    <!-- Lift actuators -->
    <position name="lift_left_upper_joint" joint="lift_left_upper_joint" kp="75000" dampratio="1.0" ctrlrange="0 0.25"/>
    <position name="lift_right_upper_joint" joint="lift_right_upper_joint" kp="75000" dampratio="1.0" ctrlrange="0 0.25"/>
    <!-- Left arm actuators -->
    <general class="size3" name="left_shoulder_pan_joint" joint="left_shoulder_pan_joint"/>
    <general class="size3" name="left_shoulder_lift_joint" joint="left_shoulder_lift_joint"/>
    <general class="size3_limited" name="left_elbow_joint" joint="left_elbow_joint"/>
    <general class="size1" name="left_wrist_1_joint" joint="left_wrist_1_joint"/>
    <general class="size1" name="left_wrist_2_joint" joint="left_wrist_2_joint"/>
    <general class="size1" name="left_wrist_3_joint" joint="left_wrist_3_joint"/>
    <!-- Right arm actuators -->
    <general class="size3" name="right_shoulder_pan_joint" joint="right_shoulder_pan_joint"/>
    <general class="size3" name="right_shoulder_lift_joint" joint="right_shoulder_lift_joint"/>
    <general class="size3_limited" name="right_elbow_joint" joint="right_elbow_joint"/>
    <general class="size1" name="right_wrist_1_joint" joint="right_wrist_1_joint"/>
    <general class="size1" name="right_wrist_2_joint" joint="right_wrist_2_joint"/>
    <general class="size1" name="right_wrist_3_joint" joint="right_wrist_3_joint"/>
    <!-- Left Robotiq -->
    <general class="2f85" name="left_robotiq_85_left_knuckle_joint" tendon="left_split" forcerange="-5 5"
             ctrlrange="0 .8" gainprm="100 0 0" biasprm="0 -100 -25"/>
    <!-- Right Robotiq -->
    <general class="2f85" name="right_robotiq_85_left_knuckle_joint" tendon="right_split" forcerange="-5 5"
             ctrlrange="0 .8" gainprm="100 0 0" biasprm="0 -100 -25"/>
  </actuator>



</mujoco>
